Workbook

Sheet 计算说明
A1: 副驾驶流转积分计算方式
A2: 副驾驶从学员到可流转状态的全过程培训积分计算，积分由12个部分组成，总分需达到210分以上才可能流转
A3: 积分类别 | B3: 计分标准
A4: 1. 改装理论 | B4: 一次通过得5分，否则0分
A5: 2. 改装模拟机 | B5: 一次通过得10分，否则0分
A6: 3. 改装本场 | B6: 一次通过得5分，否则0分
A7: 4. B类运行 | B7: 每运行1个月得3分
A8: 5. C类运行 | B8: 每运行1个月得6分
A9: 6. 欧洲报务 | B9: 获得资质10分+每月6分
A10: 7. 美加报务 | B10: 获得资质10分+每月6分
A11: 8. 西亚报务 | B11: 获得资质10分+每月6分
A12: 9. 飞行经历 | B12: C级后总经历时间×0.1
A13: 10. 历史分 | B13: 历史遗留分数，早期表格维护人加扣分总和，维持原状
A14: 11. 扣分项 | B14: 违规扣分等
... A17: 流转条件 | B17: 总积分必须大于210分
B18: 必须达到C级技术等级
B19: 必须获得欧洲报务资质
B20: 必须获得美加报务资质
B21: 本机型运行必须超过48个月
B22: C类运行必须超过3个月

Sheet 总表
A1: 员工号 | B1: 姓名 | C1: 分部 | D1: 最新等级 | E1: 积分排名 | F1: 培训状态 | G1: 考核项目 | H1: 进度预警 | I1: A1 | J1: 转A2阶段时长 | K1: A2 | L1: 转B总时长 | M1: 转B阶段时长 | N1: B | O1: 转C总时长 | P1: 转C阶段时长 | Q1: C | R1: D | S1: 欧洲报务培训时长 | T1: 欧洲报务 | U1: 美加报务培训时长 | V1: 美加报务 | W1: 西亚报务培训时长 | X1: 西亚报务 | Y1: 总分 | Z1: 改装理论一次通过 | AA1: 分数 | AB1: 改装模拟机一次通过 | AC1: 分数 | AD1: 改装本场一次通过 | AE1: 分数 | AF1: 技术等级A2-D | AG1: B类运行月数 | AH1: 分数 | AI1: C类运行月数 | AJ1: 分数 | AK1: 欧洲报务 | AL1: 欧洲报务月数 | AM1: 分数 | AN1: 美加报务 | AO1: 美加报务月数 | AP1: 分数 | AQ1: 西亚报务 | AR1: 西亚报务月数 | AS1: 分数 | AT1: 总经历时间 | AU1: 经历时间得分 | AV1: 本机型 运行月数 | AW1: 历史 | AX1: 扣分项 | AY1: 加分项 | AZ1: 更新说明
A2: 248310 | B2: 李晋诣 | C2: =VLOOKUP(B2,'姓名+分部'!A:B,2,FALSE) -> 二分部 | D2: D | E2: =IF(Q2>0,RANK(Y2,Y$2:Y$133),"无排名") -> 2 | F2: =IF(AND(Y2>1000,Q2>0,T2>0,V2>0,AV2>48,AI2>3),"可流转","继续培训") -> 可流转 | G2: =IF(N2>0,"不考核",IF(K2>0,"B",IF(I2>0,"A2",IF(I2=0,"学员",NA())))) -> 不考核 | H2: =_xlfn.IFS(N2>0,"完成考核",K2>0,K2+390,I2>0,I2+120) -> 完成考核 | I2: 43664 | J2: =IF($I2>0,IF(K2>0,DATEDIF(I2,K2,"m"),"未完成"),"学员") -> 1 | K2: 43702 | L2: =IF($I2>0,IF(N2>0,DATEDIF(I2,N2,"m"),"未完成"),"学员") -> 13 | M2: =IF($I2>0,IF(N2>0,DATEDIF(K2,N2,"m"),"未完成"),"学员") -> 12 | N2: 44079 | O2: =IF($I2>0,IF(Q2>0,DATEDIF(I2,Q2,"m"),"未完成"),"学员") -> 38 | P2: =IF($I2>0,IF(Q2>0,DATEDIF(N2,Q2,"m"),"未完成"),"学员") -> 24 | Q2: 44831 | R2: 45530 | S2: =IF($I2>0,IF(T2>0,DATEDIF(I2,T2,"m"),"未完成"),"学员") -> 12 | T2: 44056 | U2: =IF($I2>0,IF(V2>0,DATEDIF(I2,V2,"m"),"未完成"),"学员") -> 45 | V2: 45061 | W2: =IF($I2>0,IF(X2>0,DATEDIF(I2,X2,"m"),"未完成"),"学员") -> 67 | X2: 45725 | Y2: =AA2+AC2+AE2+AH2+AJ2+AM2+AP2+AS2+AW2+AX2+AY2+AU2 -> 2043.708 | Z2: 是 | AA2: =IF(Z2="是",5,0) -> 5 | AB2: 是 | AC2: =IF(AB2="是",10,0) -> 10 | AD2: 是 | AE2: =IF(AD2="是",5,0) -> 5 | AF2: =COUNTA(K2,N2,Q2,R2)*10 -> 40 | AG2: =IF(N2>0,DATEDIF(N2,TODAY(),"m"),0) -> 64 | AH2: =AG2*3 -> 192 | AI2: =IF(Q2>0,DATEDIF(Q2,TODAY(),"m"),0) -> 39 | AJ2: =AI2*6 -> 234 | AK2: =IF(T2>0,10,0) -> 10 | AL2: =IF(T2>0,DATEDIF(T2,TODAY(),"m"),0) -> 65 | AM2: =AL2*6 -> 390 | AN2: =IF(V2>0,10,0) -> 10 | AO2: =IF(V2>0,DATEDIF(V2,TODAY(),"m"),0) -> 32 | AP2: =AO2*6 -> 192 | AQ2: =IF(X2>0,10,0) -> 10 | AR2: =IF(X2>0,DATEDIF(X2,TODAY(),"m"),0) -> 10 | AS2: =AR2*6 -> 60 | AT2: =VLOOKUP(B2,经历时间!A:B,2,FALSE) -> 2742.08 | AU2: =IF(Q2>0,AT2*0.1,0) -> 274.208 | AV2: =IF(I2>0,DATEDIF(I2,TODAY(),"m"),0) -> 77 | AW2: 51.5 | AY2: =IFERROR(VLOOKUP(B2,'兼职+帮忙'!B:AF,28,FALSE),0) -> 630 | AZ2: 2025.9.15更新，截止2025年8月底，职员/兼职的分已经从头开始加上了，后续需要分部定期提供加分项。
A3: 251920 | B3: 周永富 | C3: =VLOOKUP(B3,'姓名+分部'!A:B,2,FALSE) -> 三分部 | D3: D | E3: =IF(Q3>0,RANK(Y3,Y$2:Y$133),"无排名") -> 4 | F3: =IF(AND(Y3>1000,Q3>0,T3>0,V3>0,AV3>48,AI3>3),"可流转","继续培训") -> 可流转 | G3: =IF(N3>0,"不考核",IF(K3>0,"B",IF(I3>0,"A2",IF(I3=0,"学员",NA())))) -> 不考核 | H3: =_xlfn.IFS(N3>0,"完成考核",K3>0,K3+390,I3>0,I3+120) -> 完成考核 | I3: 43728 | J3: =IF($I3>0,IF(K3>0,DATEDIF(I3,K3,"m"),"未完成"),"学员") -> 1 | K3: 43771 | L3: =IF($I3>0,IF(N3>0,DATEDIF(I3,N3,"m"),"未完成"),"学员") -> 14 | M3: =IF($I3>0,IF(N3>0,DATEDIF(K3,N3,"m"),"未完成"),"学员") -> 12 | N3: 44166 | O3: =IF($I3>0,IF(Q3>0,DATEDIF(I3,Q3,"m"),"未完成"),"学员") -> 42 | P3: =IF($I3>0,IF(Q3>0,DATEDIF(N3,Q3,"m"),"未完成"),"学员") -> 28 | Q3: 45017 | R3: 45373 | S3: =IF($I3>0,IF(T3>0,DATEDIF(I3,T3,"m"),"未完成"),"学员") -> 21 | T3: 44382 | U3: =IF($I3>0,IF(V3>0,DATEDIF(I3,V3,"m"),"未完成"),"学员") -> 10 | V3: 44043 | W3: =IF($I3>0,IF(X3>0,DATEDIF(I3,X3,"m"),"未完成"),"学员") -> 未完成 | Y3: =AA3+AC3+AE3+AH3+AJ3+AM3+AP3+AS3+AW3+AX3+AY3+AU3 -> 1946.203 | Z3: 是 | AA3: =IF(Z3="是",5,0) -> 5 | AB3: 是 | AC3: =IF(AB3="是",10,0) -> 10 | AD3: 是 | AE3: =IF(AD3="是",5,0) -> 5 | AF3: =COUNTA(K3,N3,Q3,R3)*10 -> 40 | AG3: =IF(N3>0,DATEDIF(N3,TODAY(),"m"),0) -> 61 | AH3: =AG3*3 -> 183 | AI3: =IF(Q3>0,DATEDIF(Q3,TODAY(),"m"),0) -> 33 | AJ3: =AI3*6 -> 198 | AK3: =IF(T3>0,10,0) -> 10 | AL3: =IF(T3>0,DATEDIF(T3,TODAY(),"m"),0) -> 54 | AM3: =AL3*6 -> 324 | AN3: =IF(V3>0,10,0) -> 10 | AO3: =IF(V3>0,DATEDIF(V3,TODAY(),"m"),0) -> 65 | AP3: =AO3*6 -> 390 | AQ3: =IF(X3>0,10,0) -> 0 | AR3: =IF(X3>0,DATEDIF(X3,TODAY(),"m"),0) -> 0 | AS3: =AR3*6 -> 0 | AT3: =VLOOKUP(B3,经历时间!A:B,2,FALSE) -> 2590.03 | AU3: =IF(Q3>0,AT3*0.1,0) -> 259.003 | AV3: =IF(I3>0,DATEDIF(I3,TODAY(),"m"),0) -> 75 | AW3: 32.2 | AY3: =IFERROR(VLOOKUP(B3,'兼职+帮忙'!B:AF,28,FALSE),0) -> 540 | AZ3: 2025.9.16新增谢源的帮忙加分，修复了“经历时间得分”的计算。
A4: 247692 | B4: 李鹏 | C4: =VLOOKUP(B4,'姓名+分部'!A:B,2,FALSE) -> 一分部 | D4: D | E4: =IF(Q4>0,RANK(Y4,Y$2:Y$133),"无排名") -> 1 | F4: =IF(AND(Y4>1000,Q4>0,T4>0,V4>0,AV4>48,AI4>3),"可流转","继续培训") -> 可流转 | G4: =IF(N4>0,"不考核",IF(K4>0,"B",IF(I4>0,"A2",IF(I4=0,"学员",NA())))) -> 不考核 | H4: =_xlfn.IFS(N4>0,"完成考核",K4>0,K4+390,I4>0,I4+120) -> 完成考核 | I4: 43731 | J4: =IF($I4>0,IF(K4>0,DATEDIF(I4,K4,"m"),"未完成"),"学员") -> 1 | K4: 43762 | L4: =IF($I4>0,IF(N4>0,DATEDIF(I4,N4,"m"),"未完成"),"学员") -> 19 | M4: =IF($I4>0,IF(N4>0,DATEDIF(K4,N4,"m"),"未完成"),"学员") -> 18 | N4: 44333 | O4: =IF($I4>0,IF(Q4>0,DATEDIF(I4,Q4,"m"),"未完成"),"学员") -> 43 | P4: =IF($I4>0,IF(Q4>0,DATEDIF(N4,Q4,"m"),"未完成"),"学员") -> 23 | Q4: 45061 | R4: 45919 | S4: =IF($I4>0,IF(T4>0,DATEDIF(I4,T4,"m"),"未完成"),"学员") -> 15 | T4: 44216 | U4: =IF($I4>0,IF(V4>0,DATEDIF(I4,V4,"m"),"未完成"),"学员") -> 8 | V4: 43993 | W4: =IF($I4>0,IF(X4>0,DATEDIF(I4,X4,"m"),"未完成"),"学员") -> 60 | X4: 45584 | Y4: =AA4+AC4+AE4+AH4+AJ4+AM4+AP4+AS4+AW4+AX4+AY4+AU4 -> 2098.428 | Z4: 是 | AA4: =IF(Z4="是",5,0) -> 5 | AB4: 是 | AC4: =IF(AB4="是",10,0) -> 10 | AD4: 是 | AE4: =IF(AD4="是",5,0) -> 5 | AF4: =COUNTA(K4,N4,Q4,R4)*10 -> 40 | AG4: =IF(N4>0,DATEDIF(N4,TODAY(),"m"),0) -> 55 | AH4: =AG4*3 -> 165 | AI4: =IF(Q4>0,DATEDIF(Q4,TODAY(),"m"),0) -> 32 | AJ4: =AI4*6 -> 192 | AK4: =IF(T4>0,10,0) -> 10 | AL4: =IF(T4>0,DATEDIF(T4,TODAY(),"m"),0) -> 59 | AM4: =AL4*6 -> 354 | AN4: =IF(V4>0,10,0) -> 10 | AO4: =IF(V4>0,DATEDIF(V4,TODAY(),"m"),0) -> 67 | AP4: =AO4*6 -> 402 | AQ4: =IF(X4>0,10,0) -> 10 | AR4: =IF(X4>0,DATEDIF(X4,TODAY(),"m"),0) -> 14 | AS4: =AR4*6 -> 84 | AT4: =VLOOKUP(B4,经历时间!A:B,2,FALSE) -> 2924.28 | AU4: =IF(Q4>0,AT4*0.1,0) -> 292.428 | AV4: =IF(I4>0,DATEDIF(I4,TODAY(),"m"),0) -> 75 | AW4: 34.5 | AY4: =IFERROR(VLOOKUP(B4,'兼职+帮忙'!B:AF,28,FALSE),0) -> 554.5 | AZ4: 2025.10.16职员加分改为10分/月，兼职加分改5分/月
A5: 248320 | B5: 陈利勤 | C5: =VLOOKUP(B5,'姓名+分部'!A:B,2,FALSE) -> 一分部 | D5: D | E5: =IF(Q5>0,RANK(Y5,Y$2:Y$133),"无排名") -> 3 | F5: =IF(AND(Y5>1000,Q5>0,T5>0,V5>0,AV5>48,AI5>3),"可流转","继续培训") -> 可流转 | G5: =IF(N5>0,"不考核",IF(K5>0,"B",IF(I5>0,"A2",IF(I5=0,"学员",NA())))) -> 不考核 | H5: =_xlfn.IFS(N5>0,"完成考核",K5>0,K5+390,I5>0,I5+120) -> 完成考核 | I5: 43666 | J5: =IF($I5>0,IF(K5>0,DATEDIF(I5,K5,"m"),"未完成"),"学员") -> 1 | K5: 43697 | L5: =IF($I5>0,IF(N5>0,DATEDIF(I5,N5,"m"),"未完成"),"学员") -> 16 | M5: =IF($I5>0,IF(N5>0,DATEDIF(K5,N5,"m"),"未完成"),"学员") -> 15 | N5: 44179 | O5: =IF($I5>0,IF(Q5>0,DATEDIF(I5,Q5,"m"),"未完成"),"学员") -> 41 | P5: =IF($I5>0,IF(Q5>0,DATEDIF(N5,Q5,"m"),"未完成"),"学员") -> 24 | Q5: 44925 | R5: 45574 | S5: =IF($I5>0,IF(T5>0,DATEDIF(I5,T5,"m"),"未完成"),"学员") -> 14 | T5: 44123 | U5: =IF($I5>0,IF(V5>0,DATEDIF(I5,V5,"m"),"未完成"),"学员") -> 45 | V5: 45050 | W5: =IF($I5>0,IF(X5>0,DATEDIF(I5,X5,"m"),"未完成"),"学员") -> 66 | X5: 45692 | Y5: =AA5+AC5+AE5+AH5+AJ5+AM5+AP5+AS5+AW5+AX5+AY5+AU5 -> 2017.842 | Z5: 是 | AA5: =IF(Z5="是",5,0) -> 5 | AB5: 是 | AC5: =IF(AB5="是",10,0) -> 10 | AD5: 是 | AE5: =IF(AD5="是",5,0) -> 5 | AF5: =COUNTA(K5,N5,Q5,R5)*10 -> 40 | AG5: =IF(N5>0,DATEDIF(N5,TODAY(),"m"),0) -> 61 | AH5: =AG5*3 -> 183 | AI5: =IF(Q5>0,DATEDIF(Q5,TODAY(),"m"),0) -> 36 | AJ5: =AI5*6 -> 216 | AK5: =IF(T5>0,10,0) -> 10 | AL5: =IF(T5>0,DATEDIF(T5,TODAY(),"m"),0) -> 62 | AM5: =AL5*6 -> 372 | AN5: =IF(V5>0,10,0) -> 10 | AO5: =IF(V5>0,DATEDIF(V5,TODAY(),"m"),0) -> 32 | AP5: =AO5*6 -> 192 | AQ5: =IF(X5>0,10,0) -> 10 | AR5: =IF(X5>0,DATEDIF(X5,TODAY(),"m"),0) -> 11 | AS5: =AR5*6 -> 66 | AT5: =VLOOKUP(B5,经历时间!A:B,2,FALSE) -> 2758.42 | AU5: =IF(Q5>0,AT5*0.1,0) -> 275.842 | AV5: =IF(I5>0,DATEDIF(I5,TODAY(),"m"),0) -> 77 | AW5: 63 | AY5: =IFERROR(VLOOKUP(B5,'兼职+帮忙'!B:AF,28,FALSE),0) -> 630 | AZ5: 2025.11.12更新了9月，10月技术等级，更新了总经历时间
A6: 260944 | B6: 王若飞 | C6: =VLOOKUP(B6,'姓名+分部'!A:B,2,FALSE) -> 二分部 | D6: D | E6: =IF(Q6>0,RANK(Y6,Y$2:Y$133),"无排名") -> 12 | F6: =IF(AND(Y6>1000,Q6>0,T6>0,V6>0,AV6>48,AI6>3),"可流转","继续培训") -> 可流转 | G6: =IF(N6>0,"不考核",IF(K6>0,"B",IF(I6>0,"A2",IF(I6=0,"学员",NA())))) -> 不考核 | H6: =_xlfn.IFS(N6>0,"完成考核",K6>0,K6+390,I6>0,I6+120) -> 完成考核 | I6: 44027 | J6: =IF($I6>0,IF(K6>0,DATEDIF(I6,K6,"m"),"未完成"),"学员") -> 6 | K6: 44230 | L6: =IF($I6>0,IF(N6>0,DATEDIF(I6,N6,"m"),"未完成"),"学员") -> 39 | M6: =IF($I6>0,IF(N6>0,DATEDIF(K6,N6,"m"),"未完成"),"学员") -> 32 | N6: 45220 | O6: =IF($I6>0,IF(Q6>0,DATEDIF(I6,Q6,"m"),"未完成"),"学员") -> 52 | P6: =IF($I6>0,IF(Q6>0,DATEDIF(N6,Q6,"m"),"未完成"),"学员") -> 13 | Q6: 45623 | R6: 45951 | S6: =IF($I6>0,IF(T6>0,DATEDIF(I6,T6,"m"),"未完成"),"学员") -> 27 | T6: 44858 | U6: =IF($I6>0,IF(V6>0,DATEDIF(I6,V6,"m"),"未完成"),"学员") -> 35 | V6: 45101 | W6: =IF($I6>0,IF(X6>0,DATEDIF(I6,X6,"m"),"未完成"),"学员") -> 52 | X6: 45632 | Y6: =AA6+AC6+AE6+AH6+AJ6+AM6+AP6+AS6+AW6+AX6+AY6+AU6 -> 1130.021 | Z6: 是 | AA6: =IF(Z6="是",5,0) -> 5 | AB6: 是 | AC6: =IF(AB6="是",10,0) -> 10 | AD6: 是 | AE6: =IF(AD6="是",5,0) -> 5 | AF6: =COUNTA(K6,N6,Q6,R6)*10 -> 40 | AG6: =IF(N6>0,DATEDIF(N6,TODAY(),"m"),0) -> 26 | AH6: =AG6*3 -> 78 | AI6: =IF(Q6>0,DATEDIF(Q6,TODAY(),"m"),0) -> 13 | AJ6: =AI6*6 -> 78 | AK6: =IF(T6>0,10,0) -> 10 | AL6: =IF(T6>0,DATEDIF(T6,TODAY(),"m"),0) -> 38 | AM6: =AL6*6 -> 228 | AN6: =IF(V6>0,10,0) -> 10 | AO6: =IF(V6>0,DATEDIF(V6,TODAY(),"m"),0) -> 30 | AP6: =AO6*6 -> 180 | AQ6: =IF(X6>0,10,0) -> 10 | AR6: =IF(X6>0,DATEDIF(X6,TODAY(),"m"),0) -> 13 | AS6: =AR6*6 -> 78 | AT6: =VLOOKUP(B6,经历时间!A:B,2,FALSE) -> 2240.21 | AU6: =IF(Q6>0,AT6*0.1,0) -> 224.021 | AV6: =IF(I6>0,DATEDIF(I6,TODAY(),"m"),0) -> 66 | AW6: 22 | AY6: =IFERROR(VLOOKUP(B6,'兼职+帮忙'!B:AF,28,FALSE),0) -> 222 | AZ6: 2026.1.6新增了公式说明，新增卢元俊的兼职帮忙加分
A7: 247704 | B7: 卢元俊 | C7: =VLOOKUP(B7,'姓名+分部'!A:B,2,FALSE) -> 二分部 | D7: C | E7: =IF(Q7>0,RANK(Y7,Y$2:Y$133),"无排名") -> 5 | F7: =IF(AND(Y7>1000,Q7>0,T7>0,V7>0,AV7>48,AI7>3),"可流转","继续培训") -> 可流转 | G7: =IF(N7>0,"不考核",IF(K7>0,"B",IF(I7>0,"A2",IF(I7=0,"学员",NA())))) -> 不考核 | H7: =_xlfn.IFS(N7>0,"完成考核",K7>0,K7+390,I7>0,I7+120) -> 完成考核 | I7: 43664 | J7: =IF($I7>0,IF(K7>0,DATEDIF(I7,K7,"m"),"未完成"),"学员") -> 1 | K7: 43706 | L7: =IF($I7>0,IF(N7>0,DATEDIF(I7,N7,"m"),"未完成"),"学员") -> 15 | M7: =IF($I7>0,IF(N7>0,DATEDIF(K7,N7,"m"),"未完成"),"学员") -> 13 | N7: 44126 | O7: =IF($I7>0,IF(Q7>0,DATEDIF(I7,Q7,"m"),"未完成"),"学员") -> 42 | P7: =IF($I7>0,IF(Q7>0,DATEDIF(N7,Q7,"m"),"未完成"),"学员") -> 26 | Q7: 44945 | S7: =IF($I7>0,IF(T7>0,DATEDIF(I7,T7,"m"),"未完成"),"学员") -> 12 | T7: 44046 | U7: =IF($I7>0,IF(V7>0,DATEDIF(I7,V7,"m"),"未完成"),"学员") -> 46 | V7: 45075 | W7: =IF($I7>0,IF(X7>0,DATEDIF(I7,X7,"m"),"未完成"),"学员") -> 70 | X7: 45797 | Y7: =AA7+AC7+AE7+AH7+AJ7+AM7+AP7+AS7+AW7+AX7+AY7+AU7 -> 1758.554 | Z7: 是 | AA7: =IF(Z7="是",5,0) -> 5 | AB7: 是 | AC7: =IF(AB7="是",10,0) -> 10 | AD7: 是 | AE7: =IF(AD7="是",5,0) -> 5 | AF7: =COUNTA(K7,N7,Q7,R7)*10 -> 30 | AG7: =IF(N7>0,DATEDIF(N7,TODAY(),"m"),0) -> 62 | AH7: =AG7*3 -> 186 | AI7: =IF(Q7>0,DATEDIF(Q7,TODAY(),"m"),0) -> 35 | AJ7: =AI7*6 -> 210 | AK7: =IF(T7>0,10,0) -> 10 | AL7: =IF(T7>0,DATEDIF(T7,TODAY(),"m"),0) -> 65 | AM7: =AL7*6 -> 390 | AN7: =IF(V7>0,10,0) -> 10 | AO7: =IF(V7>0,DATEDIF(V7,TODAY(),"m"),0) -> 31 | AP7: =AO7*6 -> 186 | AQ7: =IF(X7>0,10,0) -> 10 | AR7: =IF(X7>0,DATEDIF(X7,TODAY(),"m"),0) -> 7 | AS7: =AR7*6 -> 42 | AT7: =VLOOKUP(B7,经历时间!A:B,2,FALSE) -> 2913.54 | AU7: =IF(Q7>0,AT7*0.1,0) -> 291.354 | AV7: =IF(I7>0,DATEDIF(I7,TODAY(),"m"),0) -> 77 | AW7: 22.2 | AY7: =IFERROR(VLOOKUP(B7,'兼职+帮忙'!B:AF,28,FALSE),0) -> 411 | AZ7: 2026.1.12归档了2026之前的加分记录
A8: 248907 | B8: 余希 | C8: =VLOOKUP(B8,'姓名+分部'!A:B,2,FALSE) -> 三分部 | D8: D | E8: =IF(Q8>0,RANK(Y8,Y$2:Y$133),"无排名") -> 11 | F8: =IF(AND(Y8>1000,Q8>0,T8>0,V8>0,AV8>48,AI8>3),"可流转","继续培训") -> 可流转 | G8: =IF(N8>0,"不考核",IF(K8>0,"B",IF(I8>0,"A2",IF(I8=0,"学员",NA())))) -> 不考核 | H8: =_xlfn.IFS(N8>0,"完成考核",K8>0,K8+390,I8>0,I8+120) -> 完成考核 | I8: 44125 | J8: =IF($I8>0,IF(K8>0,DATEDIF(I8,K8,"m"),"未完成"),"学员") -> 1 | K8: 44185 | L8: =IF($I8>0,IF(N8>0,DATEDIF(I8,N8,"m"),"未完成"),"学员") -> 32 | M8: =IF($I8>0,IF(N8>0,DATEDIF(K8,N8,"m"),"未完成"),"学员") -> 30 | N8: 45112 | O8: =IF($I8>0,IF(Q8>0,DATEDIF(I8,Q8,"m"),"未完成"),"学员") -> 36 | P8: =IF($I8>0,IF(Q8>0,DATEDIF(N8,Q8,"m"),"未完成"),"学员") -> 4 | Q8: 45244 | R8: 45568 | S8: =IF($I8>0,IF(T8>0,DATEDIF(I8,T8,"m"),"未完成"),"学员") -> 28 | T8: 44997 | U8: =IF($I8>0,IF(V8>0,DATEDIF(I8,V8,"m"),"未完成"),"学员") -> 32 | V8: 45112 | W8: =IF($I8>0,IF(X8>0,DATEDIF(I8,X8,"m"),"未完成"),"学员") -> 51 | X8: 45696 | Y8: =AA8+AC8+AE8+AH8+AJ8+AM8+AP8+AS8+AW8+AX8+AY8+AU8 -> 1135.423 | Z8: 是 | AA8: =IF(Z8="是",5,0) -> 5 | AB8: 是 | AC8: =IF(AB8="是",10,0) -> 10 | AD8: 是 | AE8: =IF(AD8="是",5,0) -> 5 | AF8: =COUNTA(K8,N8,Q8,R8)*10 -> 40 | AG8: =IF(N8>0,DATEDIF(N8,TODAY(),"m"),0) -> 30 | AH8: =AG8*3 -> 90 | AI8: =IF(Q8>0,DATEDIF(Q8,TODAY(),"m"),0) -> 26 | AJ8: =AI8*6 -> 156 | AK8: =IF(T8>0,10,0) -> 10 | AL8: =IF(T8>0,DATEDIF(T8,TODAY(),"m"),0) -> 34 | AM8: =AL8*6 -> 204 | AN8: =IF(V8>0,10,0) -> 10 | AO8: =IF(V8>0,DATEDIF(V8,TODAY(),"m"),0) -> 30 | AP8: =AO8*6 -> 180 | AQ8: =IF(X8>0,10,0) -> 10 | AR8: =IF(X8>0,DATEDIF(X8,TODAY(),"m"),0) -> 11 | AS8: =AR8*6 -> 66 | AT8: =VLOOKUP(B8,经历时间!A:B,2,FALSE) -> 2721.23 | AU8: =IF(Q8>0,AT8*0.1,0) -> 272.123 | AV8: =IF(I8>0,DATEDIF(I8,TODAY(),"m"),0) -> 62 | AW8: -2.7 | AY8: =IFERROR(VLOOKUP(B8,'兼职+帮忙'!B:AF,28,FALSE),0) -> 150 | AZ8: 2026.1.16新增周锐豪 仁泽尧 罗浩诚运训室帮忙，从2026.1.1开始计算
A9: 259803 | B9: 任泽尧 | C9: =VLOOKUP(B9,'姓名+分部'!A:B,2,FALSE) -> 一分部 | D9: C | E9: =IF(Q9>0,RANK(Y9,Y$2:Y$133),"无排名") -> 18 | F9: =IF(AND(Y9>1000,Q9>0,T9>0,V9>0,AV9>48,AI9>3),"可流转","继续培训") -> 继续培训 | G9: =IF(N9>0,"不考核",IF(K9>0,"B",IF(I9>0,"A2",IF(I9=0,"学员",NA())))) -> 不考核 | H9: =_xlfn.IFS(N9>0,"完成考核",K9>0,K9+390,I9>0,I9+120) -> 完成考核 | I9: 43991 | J9: =IF($I9>0,IF(K9>0,DATEDIF(I9,K9,"m"),"未完成"),"学员") -> 4 | K9: 44117 | L9: =IF($I9>0,IF(N9>0,DATEDIF(I9,N9,"m"),"未完成"),"学员") -> 40 | M9: =IF($I9>0,IF(N9>0,DATEDIF(K9,N9,"m"),"未完成"),"学员") -> 36 | N9: 45229 | O9: =IF($I9>0,IF(Q9>0,DATEDIF(I9,Q9,"m"),"未完成"),"学员") -> 51 | P9: =IF($I9>0,IF(Q9>0,DATEDIF(N9,Q9,"m"),"未完成"),"学员") -> 10 | Q9: 45561 | S9: =IF($I9>0,IF(T9>0,DATEDIF(I9,T9,"m"),"未完成"),"学员") -> 28 | T9: 44847 | U9: =IF($I9>0,IF(V9>0,DATEDIF(I9,V9,"m"),"未完成"),"学员") -> 35 | V9: 45075 | W9: =IF($I9>0,IF(X9>0,DATEDIF(I9,X9,"m"),"未完成"),"学员") -> 54 | X9: 45646 | Y9: =AA9+AC9+AE9+AH9+AJ9+AM9+AP9+AS9+AW9+AX9+AY9+AU9 -> 912.834 | Z9: 是 | AA9: =IF(Z9="是",5,0) -> 5 | AB9: 是 | AC9: =IF(AB9="是",10,0) -> 10 | AD9: 是 | AE9: =IF(AD9="是",5,0) -> 5 | AF9: =COUNTA(K9,N9,Q9,R9)*10 -> 30 | AG9: =IF(N9>0,DATEDIF(N9,TODAY(),"m"),0) -> 26 | AH9: =AG9*3 -> 78 | AI9: =IF(Q9>0,DATEDIF(Q9,TODAY(),"m"),0) -> 15 | AJ9: =AI9*6 -> 90 | AK9: =IF(T9>0,10,0) -> 10 | AL9: =IF(T9>0,DATEDIF(T9,TODAY(),"m"),0) -> 39 | AM9: =AL9*6 -> 234 | AN9: =IF(V9>0,10,0) -> 10 | AO9: =IF(V9>0,DATEDIF(V9,TODAY(),"m"),0) -> 31 | AP9: =AO9*6 -> 186 | AQ9: =IF(X9>0,10,0) -> 10 | AR9: =IF(X9>0,DATEDIF(X9,TODAY(),"m"),0) -> 12 | AS9: =AR9*6 -> 72 | AT9: =VLOOKUP(B9,经历时间!A:B,2,FALSE) -> 2328.34 | AU9: =IF(Q9>0,AT9*0.1,0) -> 232.834 | AV9: =IF(I9>0,DATEDIF(I9,TODAY(),"m"),0) -> 67 | AW9: 0 | AY9: =IFERROR(VLOOKUP(B9,'兼职+帮忙'!B:AF,28,FALSE),0) -> 0
A10: 273299 | B10: 欧阳文威 | C10: =VLOOKUP(B10,'姓名+分部'!A:B,2,FALSE) -> 三分部 | D10: C | E10: =IF(Q10>0,RANK(Y10,Y$2:Y$133),"无排名") -> 8 | F10: =IF(AND(Y10>1000,Q10>0,T10>0,V10>0,AV10>48,AI10>3),"可流转","继续培训") -> 继续培训 | G10: =IF(N10>0,"不考核",IF(K10>0,"B",IF(I10>0,"A2",IF(I10=0,"学员",NA())))) -> 不考核 | H10: =_xlfn.IFS(N10>0,"完成考核",K10>0,K10+390,I10>0,I10+120) -> 完成考核 | I10: 44587 | J10: =IF($I10>0,IF(K10>0,DATEDIF(I10,K10,"m"),"未完成"),"学员") -> 11 | K10: 44922 | L10: =IF($I10>0,IF(N10>0,DATEDIF(I10,N10,"m"),"未完成"),"学员") -> 21 | M10: =IF($I10>0,IF(N10>0,DATEDIF(K10,N10,"m"),"未完成"),"学员") -> 10 | N10: 45237 | O10: =IF($I10>0,IF(Q10>0,DATEDIF(I10,Q10,"m"),"未完成"),"学员") -> 30 | P10: =IF($I10>0,IF(Q10>0,DATEDIF(N10,Q10,"m"),"未完成"),"学员") -> 8 | Q10: 45504 | S10: =IF($I10>0,IF(T10>0,DATEDIF(I10,T10,"m"),"未完成"),"学员") -> 8 | T10: 44842 | U10: =IF($I10>0,IF(V10>0,DATEDIF(I10,V10,"m"),"未完成"),"学员") -> 25 | V10: 45366 | W10: =IF($I10>0,IF(X10>0,DATEDIF(I10,X10,"m"),"未完成"),"学员") -> 34 | X10: 45643 | Y10: =AA10+AC10+AE10+AH10+AJ10+AM10+AP10+AS10+AW10+AX10+AY10+AU10 -> 1450.158 | Z10: 是 | AA10: =IF(Z10="是",5,0) -> 5 | AB10: 是 | AC10: =IF(AB10="是",10,0) -> 10 | AD10: 是 | AE10: =IF(AD10="是",5,0) -> 5 | AF10: =COUNTA(K10,N10,Q10,R10)*10 -> 30 | AG10: =IF(N10>0,DATEDIF(N10,TODAY(),"m"),0) -> 26 | AH10: =AG10*3 -> 78 | AI10: =IF(Q10>0,DATEDIF(Q10,TODAY(),"m"),0) -> 17 | AJ10: =AI10*6 -> 102 | AK10: =IF(T10>0,10,0) -> 10 | AL10: =IF(T10>0,DATEDIF(T10,TODAY(),"m"),0) -> 39 | AM10: =AL10*6 -> 234 | AN10: =IF(V10>0,10,0) -> 10 | AO10: =IF(V10>0,DATEDIF(V10,TODAY(),"m"),0) -> 22 | AP10: =AO10*6 -> 132 | AQ10: =IF(X10>0,10,0) -> 10 | AR10: =IF(X10>0,DATEDIF(X10,TODAY(),"m"),0) -> 12 | AS10: =AR10*6 -> 72 | AT10: =VLOOKUP(B10,经历时间!A:B,2,FALSE) -> 1751.58 | AU10: =IF(Q10>0,AT10*0.1,0) -> 175.158 | AV10: =IF(I10>0,DATEDIF(I10,TODAY(),"m"),0) -> 47 | AW10: 25 | AY10: =IFERROR(VLOOKUP(B10,'兼职+帮忙'!B:AF,28,FALSE),0) -> 612
A11: 258463 | B11: 唐鑫魁 | C11: =VLOOKUP(B11,'姓名+分部'!A:B,2,FALSE) -> 二分部 | D11: C | E11: =IF(Q11>0,RANK(Y11,Y$2:Y$133),"无排名") -> 10 | F11: =IF(AND(Y11>1000,Q11>0,T11>0,V11>0,AV11>48,AI11>3),"可流转","继续培训") -> 可流转 | G11: =IF(N11>0,"不考核",IF(K11>0,"B",IF(I11>0,"A2",IF(I11=0,"学员",NA())))) -> 不考核 | H11: =_xlfn.IFS(N11>0,"完成考核",K11>0,K11+390,I11>0,I11+120) -> 完成考核 | I11: 43901 | J11: =IF($I11>0,IF(K11>0,DATEDIF(I11,K11,"m"),"未完成"),"学员") -> 7 | K11: 44117 | L11: =IF($I11>0,IF(N11>0,DATEDIF(I11,N11,"m"),"未完成"),"学员") -> 42 | M11: =IF($I11>0,IF(N11>0,DATEDIF(K11,N11,"m"),"未完成"),"学员") -> 35 | N11: 45187 | O11: =IF($I11>0,IF(Q11>0,DATEDIF(I11,Q11,"m"),"未完成"),"学员") -> 53 | P11: =IF($I11>0,IF(Q11>0,DATEDIF(N11,Q11,"m"),"未完成"),"学员") -> 11 | Q11: 45545 | S11: =IF($I11>0,IF(T11>0,DATEDIF(I11,T11,"m"),"未完成"),"学员") -> 32 | T11: 44884 | U11: =IF($I11>0,IF(V11>0,DATEDIF(I11,V11,"m"),"未完成"),"学员") -> 44 | V11: 45258 | W11: =IF($I11>0,IF(X11>0,DATEDIF(I11,X11,"m"),"未完成"),"学员") -> 未完成 | Y11: =AA11+AC11+AE11+AH11+AJ11+AM11+AP11+AS11+AW11+AX11+AY11+AU11 -> 1166.855 | Z11: 是 | AA11: =IF(Z11="是",5,0) -> 5 | AB11: 是 | AC11: =IF(AB11="是",10,0) -> 10 | AD11: 是 | AE11: =IF(AD11="是",5,0) -> 5 | AF11: =COUNTA(K11,N11,Q11,R11)*10 -> 30 | AG11: =IF(N11>0,DATEDIF(N11,TODAY(),"m"),0) -> 27 | AH11: =AG11*3 -> 81 | AI11: =IF(Q11>0,DATEDIF(Q11,TODAY(),"m"),0) -> 16 | AJ11: =AI11*6 -> 96 | AK11: =IF(T11>0,10,0) -> 10 | AL11: =IF(T11>0,DATEDIF(T11,TODAY(),"m"),0) -> 37 | AM11: =AL11*6 -> 222 | AN11: =IF(V11>0,10,0) -> 10 | AO11: =IF(V11>0,DATEDIF(V11,TODAY(),"m"),0) -> 25 | AP11: =AO11*6 -> 150 | AQ11: =IF(X11>0,10,0) -> 0 | AR11: =IF(X11>0,DATEDIF(X11,TODAY(),"m"),0) -> 0 | AS11: =AR11*6 -> 0 | AT11: =VLOOKUP(B11,经历时间!A:B,2,FALSE) -> 2481.55 | AU11: =IF(Q11>0,AT11*0.1,0) -> 248.155 | AV11: =IF(I11>0,DATEDIF(I11,TODAY(),"m"),0) -> 70 | AW11: 21.7 | AY11: =IFERROR(VLOOKUP(B11,'兼职+帮忙'!B:AF,28,FALSE),0) -> 328
A12: 262062 | B12: 傅燧旭 | C12: =VLOOKUP(B12,'姓名+分部'!A:B,2,FALSE) -> 三分部 | D12: C | E12: =IF(Q12>0,RANK(Y12,Y$2:Y$133),"无排名") -> 14 | F12: =IF(AND(Y12>1000,Q12>0,T12>0,V12>0,AV12>48,AI12>3),"可流转","继续培训") -> 可流转 | G12: =IF(N12>0,"不考核",IF(K12>0,"B",IF(I12>0,"A2",IF(I12=0,"学员",NA())))) -> 不考核 | H12: =_xlfn.IFS(N12>0,"完成考核",K12>0,K12+390,I12>0,I12+120) -> 完成考核 | I12: 44027 | J12: =IF($I12>0,IF(K12>0,DATEDIF(I12,K12,"m"),"未完成"),"学员") -> 9 | K12: 44323 | L12: =IF($I12>0,IF(N12>0,DATEDIF(I12,N12,"m"),"未完成"),"学员") -> 39 | M12: =IF($I12>0,IF(N12>0,DATEDIF(K12,N12,"m"),"未完成"),"学员") -> 29 | N12: 45215 | O12: =IF($I12>0,IF(Q12>0,DATEDIF(I12,Q12,"m"),"未完成"),"学员") -> 51 | P12: =IF($I12>0,IF(Q12>0,DATEDIF(N12,Q12,"m"),"未完成"),"学员") -> 12 | Q12: 45587 | S12: =IF($I12>0,IF(T12>0,DATEDIF(I12,T12,"m"),"未完成"),"学员") -> 24 | T12: 44778 | U12: =IF($I12>0,IF(V12>0,DATEDIF(I12,V12,"m"),"未完成"),"学员") -> 37 | V12: 45159 | W12: =IF($I12>0,IF(X12>0,DATEDIF(I12,X12,"m"),"未完成"),"学员") -> 未完成 | Y12: =AA12+AC12+AE12+AH12+AJ12+AM12+AP12+AS12+AW12+AX12+AY12+AU12 -> 1032.841 | Z12: 是 | AA12: =IF(Z12="是",5,0) -> 5 | AB12: 是 | AC12: =IF(AB12="是",10,0) -> 10 | AD12: 是 | AE12: =IF(AD12="是",5,0) -> 5 | AF12: =COUNTA(K12,N12,Q12,R12)*10 -> 30 | AG12: =IF(N12>0,DATEDIF(N12,TODAY(),"m"),0) -> 27 | AH12: =AG12*3 -> 81 | AI12: =IF(Q12>0,DATEDIF(Q12,TODAY(),"m"),0) -> 14 | AJ12: =AI12*6 -> 84 | AK12: =IF(T12>0,10,0) -> 10 | AL12: =IF(T12>0,DATEDIF(T12,TODAY(),"m"),0) -> 41 | AM12: =AL12*6 -> 246 | AN12: =IF(V12>0,10,0) -> 10 | AO12: =IF(V12>0,DATEDIF(V12,TODAY(),"m"),0) -> 28 | AP12: =AO12*6 -> 168 | AQ12: =IF(X12>0,10,0) -> 0 | AR12: =IF(X12>0,DATEDIF(X12,TODAY(),"m"),0) -> 0 | AS12: =AR12*6 -> 0 | AT12: =VLOOKUP(B12,经历时间!A:B,2,FALSE) -> 2335.41 | AU12: =IF(Q12>0,AT12*0.1,0) -> 233.541 | AV12: =IF(I12>0,DATEDIF(I12,TODAY(),"m"),0) -> 66 | AW12: 8.3 | AY12: =IFERROR(VLOOKUP(B12,'兼职+帮忙'!B:AF,28,FALSE),0) -> 192
A13: 259806 | B13: 全棣伟 | C13: =VLOOKUP(B13,'姓名+分部'!A:B,2,FALSE) -> 一分部 | D13: D | E13: =IF(Q13>0,RANK(Y13,Y$2:Y$133),"无排名") -> 17 | F13: =IF(AND(Y13>1000,Q13>0,T13>0,V13>0,AV13>48,AI13>3),"可流转","继续培训") -> 继续培训 | G13: =IF(N13>0,"不考核",IF(K13>0,"B",IF(I13>0,"A2",IF(I13=0,"学员",NA())))) -> 不考核 | H13: =_xlfn.IFS(N13>0,"完成考核",K13>0,K13+390,I13>0,I13+120) -> 完成考核 | I13: 44025 | J13: =IF($I13>0,IF(K13>0,DATEDIF(I13,K13,"m"),"未完成"),"学员") -> 6 | K13: 44212 | L13: =IF($I13>0,IF(N13>0,DATEDIF(I13,N13,"m"),"未完成"),"学员") -> 24 | M13: =IF($I13>0,IF(N13>0,DATEDIF(K13,N13,"m"),"未完成"),"学员") -> 17 | N13: 44757 | O13: =IF($I13>0,IF(Q13>0,DATEDIF(I13,Q13,"m"),"未完成"),"学员") -> 37 | P13: =IF($I13>0,IF(Q13>0,DATEDIF(N13,Q13,"m"),"未完成"),"学员") -> 13 | Q13: 45159 | R13: 45561 | S13: =IF($I13>0,IF(T13>0,DATEDIF(I13,T13,"m"),"未完成"),"学员") -> 21 | T13: 44681 | U13: =IF($I13>0,IF(V13>0,DATEDIF(I13,V13,"m"),"未完成"),"学员") -> 44 | V13: 45373 | W13: =IF($I13>0,IF(X13>0,DATEDIF(I13,X13,"m"),"未完成"),"学员") -> 未完成 | Y13: =AA13+AC13+AE13+AH13+AJ13+AM13+AP13+AS13+AW13+AX13+AY13+AU13 -> 915.726 | Z13: 是 | AA13: =IF(Z13="是",5,0) -> 5 | AB13: 是 | AC13: =IF(AB13="是",10,0) -> 10 | AD13: 是 | AE13: =IF(AD13="是",5,0) -> 5 | AF13: =COUNTA(K13,N13,Q13,R13)*10 -> 40 | AG13: =IF(N13>0,DATEDIF(N13,TODAY(),"m"),0) -> 42 | AH13: =AG13*3 -> 126 | AI13: =IF(Q13>0,DATEDIF(Q13,TODAY(),"m"),0) -> 28 | AJ13: =AI13*6 -> 168 | AK13: =IF(T13>0,10,0) -> 10 | AL13: =IF(T13>0,DATEDIF(T13,TODAY(),"m"),0) -> 44 | AM13: =AL13*6 -> 264 | AN13: =IF(V13>0,10,0) -> 10 | AO13: =IF(V13>0,DATEDIF(V13,TODAY(),"m"),0) -> 21 | AP13: =AO13*6 -> 126 | AQ13: =IF(X13>0,10,0) -> 0 | AR13: =IF(X13>0,DATEDIF(X13,TODAY(),"m"),0) -> 0 | AS13: =AR13*6 -> 0 | AT13: =VLOOKUP(B13,经历时间!A:B,2,FALSE) -> 2098.26 | AU13: =IF(Q13>0,AT13*0.1,0) -> 209.826 | AV13: =IF(I13>0,DATEDIF(I13,TODAY(),"m"),0) -> 66 | AW13: 1.9 | AY13: =IFERROR(VLOOKUP(B13,'兼职+帮忙'!B:AF,28,FALSE),0) -> 0
A14: 263416 | B14: 黄俊豪 | C14: =VLOOKUP(B14,'姓名+分部'!A:B,2,FALSE) -> 一分部 | D14: C | E14: =IF(Q14>0,RANK(Y14,Y$2:Y$133),"无排名") -> 20 | F14: =IF(AND(Y14>1000,Q14>0,T14>0,V14>0,AV14>48,AI14>3),"可流转","继续培训") -> 继续培训 | G14: =IF(N14>0,"不考核",IF(K14>0,"B",IF(I14>0,"A2",IF(I14=0,"学员",NA())))) -> 不考核 | H14: =_xlfn.IFS(N14>0,"完成考核",K14>0,K14+390,I14>0,I14+120) -> 完成考核 | I14: 44416 | J14: =IF($I14>0,IF(K14>0,DATEDIF(I14,K14,"m"),"未完成"),"学员") -> 5 | K14: 44589 | L14: =IF($I14>0,IF(N14>0,DATEDIF(I14,N14,"m"),"未完成"),"学员") -> 26 | M14: =IF($I14>0,IF(N14>0,DATEDIF(K14,N14,"m"),"未完成"),"学员") -> 20 | N14: 45220 | O14: =IF($I14>0,IF(Q14>0,DATEDIF(I14,Q14,"m"),"未完成"),"学员") -> 42 | P14: =IF($I14>0,IF(Q14>0,DATEDIF(N14,Q14,"m"),"未完成"),"学员") -> 16 | Q14: 45714 | S14: =IF($I14>0,IF(T14>0,DATEDIF(I14,T14,"m"),"未完成"),"学员") -> 19 | T14: 45009 | U14: =IF($I14>0,IF(V14>0,DATEDIF(I14,V14,"m"),"未完成"),"学员") -> 36 | V14: 45512 | W14: =IF($I14>0,IF(X14>0,DATEDIF(I14,X14,"m"),"未完成"),"学员") -> 未完成 | Y14: =AA14+AC14+AE14+AH14+AJ14+AM14+AP14+AS14+AW14+AX14+AY14+AU14 -> 830.419 | Z14: 是 | AA14: =IF(Z14="是",5,0) -> 5 | AB14: 是 | AC14: =IF(AB14="是",10,0) -> 10 | AD14: 是 | AE14: =IF(AD14="是",5,0) -> 5 | AF14: =COUNTA(K14,N14,Q14,R14)*10 -> 30 | AG14: =IF(N14>0,DATEDIF(N14,TODAY(),"m"),0) -> 26 | AH14: =AG14*3 -> 78 | AI14: =IF(Q14>0,DATEDIF(Q14,TODAY(),"m"),0) -> 10 | AJ14: =AI14*6 -> 60 | AK14: =IF(T14>0,10,0) -> 10 | AL14: =IF(T14>0,DATEDIF(T14,TODAY(),"m"),0) -> 33 | AM14: =AL14*6 -> 198 | AN14: =IF(V14>0,10,0) -> 10 | AO14: =IF(V14>0,DATEDIF(V14,TODAY(),"m"),0) -> 17 | AP14: =AO14*6 -> 102 | AQ14: =IF(X14>0,10,0) -> 0 | AR14: =IF(X14>0,DATEDIF(X14,TODAY(),"m"),0) -> 0 | AS14: =AR14*6 -> 0 | AT14: =VLOOKUP(B14,经历时间!A:B,2,FALSE) -> 2074.19 | AU14: =IF(Q14>0,AT14*0.1,0) -> 207.419 | AV14: =IF(I14>0,DATEDIF(I14,TODAY(),"m"),0) -> 53 | AW14: 21.5 | AX14: -5 | AY14: =IFERROR(VLOOKUP(B14,'兼职+帮忙'!B:AF,28,FALSE),0) -> 148.5
A15: 251924 | B15: 覃盼阳 | C15: =VLOOKUP(B15,'姓名+分部'!A:B,2,FALSE) -> 一分部 | D15: C | E15: =IF(Q15>0,RANK(Y15,Y$2:Y$133),"无排名") -> 13 | F15: =IF(AND(Y15>1000,Q15>0,T15>0,V15>0,AV15>48,AI15>3),"可流转","继续培训") -> 可流转 | G15: =IF(N15>0,"不考核",IF(K15>0,"B",IF(I15>0,"A2",IF(I15=0,"学员",NA())))) -> 不考核 | H15: =_xlfn.IFS(N15>0,"完成考核",K15>0,K15+390,I15>0,I15+120) -> 完成考核 | I15: 43825 | J15: =IF($I15>0,IF(K15>0,DATEDIF(I15,K15,"m"),"未完成"),"学员") -> 6 | K15: 44031 | L15: =IF($I15>0,IF(N15>0,DATEDIF(I15,N15,"m"),"未完成"),"学员") -> 30 | M15: =IF($I15>0,IF(N15>0,DATEDIF(K15,N15,"m"),"未完成"),"学员") -> 23 | N15: 44752 | O15: =IF($I15>0,IF(Q15>0,DATEDIF(I15,Q15,"m"),"未完成"),"学员") -> 39 | P15: =IF($I15>0,IF(Q15>0,DATEDIF(N15,Q15,"m"),"未完成"),"学员") -> 8 | Q15: 45017 | S15: =IF($I15>0,IF(T15>0,DATEDIF(I15,T15,"m"),"未完成"),"学员") -> 41 | T15: 45085 | U15: =IF($I15>0,IF(V15>0,DATEDIF(I15,V15,"m"),"未完成"),"学员") -> 41 | V15: 45085 | W15: =IF($I15>0,IF(X15>0,DATEDIF(I15,X15,"m"),"未完成"),"学员") -> 61 | X15: 45703 | Y15: =AA15+AC15+AE15+AH15+AJ15+AM15+AP15+AS15+AW15+AX15+AY15+AU15 -> 1041.443 | Z15: 是 | AA15: =IF(Z15="是",5,0) -> 5 | AB15: 是 | AC15: =IF(AB15="是",10,0) -> 10 | AD15: 是 | AE15: =IF(AD15="是",5,0) -> 5 | AF15: =COUNTA(K15,N15,Q15,R15)*10 -> 30 | AG15: =IF(N15>0,DATEDIF(N15,TODAY(),"m"),0) -> 42 | AH15: =AG15*3 -> 126 | AI15: =IF(Q15>0,DATEDIF(Q15,TODAY(),"m"),0) -> 33 | AJ15: =AI15*6 -> 198 | AK15: =IF(T15>0,10,0) -> 10 | AL15: =IF(T15>0,DATEDIF(T15,TODAY(),"m"),0) -> 31 | AM15: =AL15*6 -> 186 | AN15: =IF(V15>0,10,0) -> 10 | AO15: =IF(V15>0,DATEDIF(V15,TODAY(),"m"),0) -> 31 | AP15: =AO15*6 -> 186 | AQ15: =IF(X15>0,10,0) -> 10 | AR15: =IF(X15>0,DATEDIF(X15,TODAY(),"m"),0) -> 11 | AS15: =AR15*6 -> 66 | AT15: =VLOOKUP(B15,经历时间!A:B,2,FALSE) -> 2559.43 | AU15: =IF(Q15>0,AT15*0.1,0) -> 255.943 | AV15: =IF(I15>0,DATEDIF(I15,TODAY(),"m"),0) -> 72 | AW15: 3.5 | AY15: =IFERROR(VLOOKUP(B15,'兼职+帮忙'!B:AF,28,FALSE),0) -> 0
A16: 265801 | B16: 刘展亮 | C16: =VLOOKUP(B16,'姓名+分部'!A:B,2,FALSE) -> 二分部 | D16: C | E16: =IF(Q16>0,RANK(Y16,Y$2:Y$133),"无排名") -> 21 | F16: =IF(AND(Y16>1000,Q16>0,T16>0,V16>0,AV16>48,AI16>3),"可流转","继续培训") -> 继续培训 | G16: =IF(N16>0,"不考核",IF(K16>0,"B",IF(I16>0,"A2",IF(I16=0,"学员",NA())))) -> 不考核 | H16: =_xlfn.IFS(N16>0,"完成考核",K16>0,K16+390,I16>0,I16+120) -> 完成考核 | I16: 44421 | J16: =IF($I16>0,IF(K16>0,DATEDIF(I16,K16,"m"),"未完成"),"学员") -> 19 | K16: 45009 | L16: =IF($I16>0,IF(N16>0,DATEDIF(I16,N16,"m"),"未完成"),"学员") -> 29 | M16: =IF($I16>0,IF(N16>0,DATEDIF(K16,N16,"m"),"未完成"),"学员") -> 10 | N16: 45327 | O16: =IF($I16>0,IF(Q16>0,DATEDIF(I16,Q16,"m"),"未完成"),"学员") -> 42 | P16: =IF($I16>0,IF(Q16>0,DATEDIF(N16,Q16,"m"),"未完成"),"学员") -> 13 | Q16: 45727 | S16: =IF($I16>0,IF(T16>0,DATEDIF(I16,T16,"m"),"未完成"),"学员") -> 22 | T16: 45112 | U16: =IF($I16>0,IF(V16>0,DATEDIF(I16,V16,"m"),"未完成"),"学员") -> 28 | V16: 45286 | W16: =IF($I16>0,IF(X16>0,DATEDIF(I16,X16,"m"),"未完成"),"学员") -> 42 | X16: 45709 | Y16: =AA16+AC16+AE16+AH16+AJ16+AM16+AP16+AS16+AW16+AX16+AY16+AU16 -> 744.155 | Z16: 是 | AA16: =IF(Z16="是",5,0) -> 5 | AB16: 是 | AC16: =IF(AB16="是",10,0) -> 10 | AD16: 是 | AE16: =IF(AD16="是",5,0) -> 5 | AF16: =COUNTA(K16,N16,Q16,R16)*10 -> 30 | AG16: =IF(N16>0,DATEDIF(N16,TODAY(),"m"),0) -> 23 | AH16: =AG16*3 -> 69 | AI16: =IF(Q16>0,DATEDIF(Q16,TODAY(),"m"),0) -> 10 | AJ16: =AI16*6 -> 60 | AK16: =IF(T16>0,10,0) -> 10 | AL16: =IF(T16>0,DATEDIF(T16,TODAY(),"m"),0) -> 30 | AM16: =AL16*6 -> 180 | AN16: =IF(V16>0,10,0) -> 10 | AO16: =IF(V16>0,DATEDIF(V16,TODAY(),"m"),0) -> 24 | AP16: =AO16*6 -> 144 | AQ16: =IF(X16>0,10,0) -> 10 | AR16: =IF(X16>0,DATEDIF(X16,TODAY(),"m"),0) -> 10 | AS16: =AR16*6 -> 60 | AT16: =VLOOKUP(B16,经历时间!A:B,2,FALSE) -> 1994.55 | AU16: =IF(Q16>0,AT16*0.1,0) -> 199.455 | AV16: =IF(I16>0,DATEDIF(I16,TODAY(),"m"),0) -> 53 | AW16: 7.7 | AY16: =IFERROR(VLOOKUP(B16,'兼职+帮忙'!B:AF,28,FALSE),0) -> 4
A17: 248322 | B17: 沙思丞 | C17: =VLOOKUP(B17,'姓名+分部'!A:B,2,FALSE) -> 一分部 | D17: C | E17: =IF(Q17>0,RANK(Y17,Y$2:Y$133),"无排名") -> 19 | F17: =IF(AND(Y17>1000,Q17>0,T17>0,V17>0,AV17>48,AI17>3),"可流转","继续培训") -> 继续培训 | G17: =IF(N17>0,"不考核",IF(K17>0,"B",IF(I17>0,"A2",IF(I17=0,"学员",NA())))) -> 不考核 | H17: =_xlfn.IFS(N17>0,"完成考核",K17>0,K17+390,I17>0,I17+120) -> 完成考核 | I17: 43664 | J17: =IF($I17>0,IF(K17>0,DATEDIF(I17,K17,"m"),"未完成"),"学员") -> 1 | K17: 43697 | L17: =IF($I17>0,IF(N17>0,DATEDIF(I17,N17,"m"),"未完成"),"学员") -> 26 | M17: =IF($I17>0,IF(N17>0,DATEDIF(K17,N17,"m"),"未完成"),"学员") -> 24 | N17: 44457 | O17: =IF($I17>0,IF(Q17>0,DATEDIF(I17,Q17,"m"),"未完成"),"学员") -> 59 | P17: =IF($I17>0,IF(Q17>0,DATEDIF(N17,Q17,"m"),"未完成"),"学员") -> 33 | Q17: 45467 | S17: =IF($I17>0,IF(T17>0,DATEDIF(I17,T17,"m"),"未完成"),"学员") -> 42 | T17: 44958 | U17: =IF($I17>0,IF(V17>0,DATEDIF(I17,V17,"m"),"未完成"),"学员") -> 57 | V17: 45406 | W17: =IF($I17>0,IF(X17>0,DATEDIF(I17,X17,"m"),"未完成"),"学员") -> 未完成 | Y17: =AA17+AC17+AE17+AH17+AJ17+AM17+AP17+AS17+AW17+AX17+AY17+AU17 -> 870.517 | Z17: 是 | AA17: =IF(Z17="是",5,0) -> 5 | AB17: 是 | AC17: =IF(AB17="是",10,0) -> 10 | AD17: 是 | AE17: =IF(AD17="是",5,0) -> 5 | AF17: =COUNTA(K17,N17,Q17,R17)*10 -> 30 | AG17: =IF(N17>0,DATEDIF(N17,TODAY(),"m"),0) -> 51 | AH17: =AG17*3 -> 153 | AI17: =IF(Q17>0,DATEDIF(Q17,TODAY(),"m"),0) -> 18 | AJ17: =AI17*6 -> 108 | AK17: =IF(T17>0,10,0) -> 10 | AL17: =IF(T17>0,DATEDIF(T17,TODAY(),"m"),0) -> 35 | AM17: =AL17*6 -> 210 | AN17: =IF(V17>0,10,0) -> 10 | AO17: =IF(V17>0,DATEDIF(V17,TODAY(),"m"),0) -> 20 | AP17: =AO17*6 -> 120 | AQ17: =IF(X17>0,10,0) -> 0 | AR17: =IF(X17>0,DATEDIF(X17,TODAY(),"m"),0) -> 0 | AS17: =AR17*6 -> 0 | AT17: =VLOOKUP(B17,经历时间!A:B,2,FALSE) -> 2640.17 | AU17: =IF(Q17>0,AT17*0.1,0) -> 264.017 | AV17: =IF(I17>0,DATEDIF(I17,TODAY(),"m"),0) -> 77 | AW17: -4.5 | AY17: =IFERROR(VLOOKUP(B17,'兼职+帮忙'!B:AF,28,FALSE),0) -> 0
A18: 257606 | B18: 陈伟雄 | C18: =VLOOKUP(B18,'姓名+分部'!A:B,2,FALSE) -> 二分部 | D18: C | E18: =IF(Q18>0,RANK(Y18,Y$2:Y$133),"无排名") -> 16 | F18: =IF(AND(Y18>1000,Q18>0,T18>0,V18>0,AV18>48,AI18>3),"可流转","继续培训") -> 可流转 | G18: =IF(N18>0,"不考核",IF(K18>0,"B",IF(I18>0,"A2",IF(I18=0,"学员",NA())))) -> 不考核 | H18: =_xlfn.IFS(N18>0,"完成考核",K18>0,K18+390,I18>0,I18+120) -> 完成考核 | I18: 43865 | J18: =IF($I18>0,IF(K18>0,DATEDIF(I18,K18,"m"),"未完成"),"学员") -> 9 | K18: 44142 | L18: =IF($I18>0,IF(N18>0,DATEDIF(I18,N18,"m"),"未完成"),"学员") -> 28 | M18: =IF($I18>0,IF(N18>0,DATEDIF(K18,N18,"m"),"未完成"),"学员") -> 19 | N18: 44745 | O18: =IF($I18>0,IF(Q18>0,DATEDIF(I18,Q18,"m"),"未完成"),"学员") -> 42 | P18: =IF($I18>0,IF(Q18>0,DATEDIF(N18,Q18,"m"),"未完成"),"学员") -> 13 | Q18: 45169 | S18: =IF($I18>0,IF(T18>0,DATEDIF(I18,T18,"m"),"未完成"),"学员") -> 27 | T18: 44687 | U18: =IF($I18>0,IF(V18>0,DATEDIF(I18,V18,"m"),"未完成"),"学员") -> 39 | V18: 45075 | W18: =IF($I18>0,IF(X18>0,DATEDIF(I18,X18,"m"),"未完成"),"学员") -> 未完成 | Y18: =AA18+AC18+AE18+AH18+AJ18+AM18+AP18+AS18+AW18+AX18+AY18+AU18 -> 1010.237 | Z18: 是 | AA18: =IF(Z18="是",5,0) -> 5 | AB18: 是 | AC18: =IF(AB18="是",10,0) -> 10 | AD18: 是 | AE18: =IF(AD18="是",5,0) -> 5 | AF18: =COUNTA(K18,N18,Q18,R18)*10 -> 30 | AG18: =IF(N18>0,DATEDIF(N18,TODAY(),"m"),0) -> 42 | AH18: =AG18*3 -> 126 | AI18: =IF(Q18>0,DATEDIF(Q18,TODAY(),"m"),0) -> 28 | AJ18: =AI18*6 -> 168 | AK18: =IF(T18>0,10,0) -> 10 | AL18: =IF(T18>0,DATEDIF(T18,TODAY(),"m"),0) -> 44 | AM18: =AL18*6 -> 264 | AN18: =IF(V18>0,10,0) -> 10 | AO18: =IF(V18>0,DATEDIF(V18,TODAY(),"m"),0) -> 31 | AP18: =AO18*6 -> 186 | AQ18: =IF(X18>0,10,0) -> 0 | AR18: =IF(X18>0,DATEDIF(X18,TODAY(),"m"),0) -> 0 | AS18: =AR18*6 -> 0 | AT18: =VLOOKUP(B18,经历时间!A:B,2,FALSE) -> 2342.37 | AU18: =IF(Q18>0,AT18*0.1,0) -> 234.237 | AV18: =IF(I18>0,DATEDIF(I18,TODAY(),"m"),0) -> 71 | AW18: 7 | AY18: =IFERROR(VLOOKUP(B18,'兼职+帮忙'!B:AF,28,FALSE),0) -> 5
A19: 240677 | B19: 吴润雨 | C19: =VLOOKUP(B19,'姓名+分部'!A:B,2,FALSE) -> 二分部 | D19: D | E19: =IF(Q19>0,RANK(Y19,Y$2:Y$133),"无排名") -> 7 | F19: =IF(AND(Y19>1000,Q19>0,T19>0,V19>0,AV19>48,AI19>3),"可流转","继续培训") -> 可流转 | G19: =IF(N19>0,"不考核",IF(K19>0,"B",IF(I19>0,"A2",IF(I19=0,"学员",NA())))) -> 不考核 | H19: =_xlfn.IFS(N19>0,"完成考核",K19>0,K19+390,I19>0,I19+120) -> 完成考核 | I19: 43480 | J19: =IF($I19>0,IF(K19>0,DATEDIF(I19,K19,"m"),"未完成"),"学员") -> 2 | K19: 43553 | L19: =IF($I19>0,IF(N19>0,DATEDIF(I19,N19,"m"),"未完成"),"学员") -> 18 | M19: =IF($I19>0,IF(N19>0,DATEDIF(K19,N19,"m"),"未完成"),"学员") -> 15 | N19: 44035 | O19: =IF($I19>0,IF(Q19>0,DATEDIF(I19,Q19,"m"),"未完成"),"学员") -> 44 | P19: =IF($I19>0,IF(Q19>0,DATEDIF(N19,Q19,"m"),"未完成"),"学员") -> 26 | Q19: 44835 | R19: 45441 | S19: =IF($I19>0,IF(T19>0,DATEDIF(I19,T19,"m"),"未完成"),"学员") -> 18 | T19: 44046 | U19: =IF($I19>0,IF(V19>0,DATEDIF(I19,V19,"m"),"未完成"),"学员") -> 16 | V19: 43993 | W19: =IF($I19>0,IF(X19>0,DATEDIF(I19,X19,"m"),"未完成"),"学员") -> 69 | X19: 45597 | Y19: =AA19+AC19+AE19+AH19+AJ19+AM19+AP19+AS19+AW19+AX19+AY19+AU19 -> 1628.713 | Z19: 是 | AA19: =IF(Z19="是",5,0) -> 5 | AB19: 是 | AC19: =IF(AB19="是",10,0) -> 10 | AD19: 是 | AE19: =IF(AD19="是",5,0) -> 5 | AF19: =COUNTA(K19,N19,Q19,R19)*10 -> 40 | AG19: =IF(N19>0,DATEDIF(N19,TODAY(),"m"),0) -> 65 | AH19: =AG19*3 -> 195 | AI19: =IF(Q19>0,DATEDIF(Q19,TODAY(),"m"),0) -> 39 | AJ19: =AI19*6 -> 234 | AK19: =IF(T19>0,10,0) -> 10 | AL19: =IF(T19>0,DATEDIF(T19,TODAY(),"m"),0) -> 65 | AM19: =AL19*6 -> 390 | AN19: =IF(V19>0,10,0) -> 10 | AO19: =IF(V19>0,DATEDIF(V19,TODAY(),"m"),0) -> 67 | AP19: =AO19*6 -> 402 | AQ19: =IF(X19>0,10,0) -> 10 | AR19: =IF(X19>0,DATEDIF(X19,TODAY(),"m"),0) -> 14 | AS19: =AR19*6 -> 84 | AT19: =VLOOKUP(B19,经历时间!A:B,2,FALSE) -> 3037.13 | AU19: =IF(Q19>0,AT19*0.1,0) -> 303.713 | AV19: =IF(I19>0,DATEDIF(I19,TODAY(),"m"),0) -> 84 | AW19: 0 | AY19: =IFERROR(VLOOKUP(B19,'兼职+帮忙'!B:AF,28,FALSE),0) -> 0
A20: 248319 | B20: 吴振鹏 | C20: =VLOOKUP(B20,'姓名+分部'!A:B,2,FALSE) -> 一分部 | D20: C | E20: =IF(Q20>0,RANK(Y20,Y$2:Y$133),"无排名") -> 15 | F20: =IF(AND(Y20>1000,Q20>0,T20>0,V20>0,AV20>48,AI20>3),"可流转","继续培训") -> 可流转 | G20: =IF(N20>0,"不考核",IF(K20>0,"B",IF(I20>0,"A2",IF(I20=0,"学员",NA())))) -> 不考核 | H20: =_xlfn.IFS(N20>0,"完成考核",K20>0,K20+390,I20>0,I20+120) -> 完成考核 | I20: 43782 | J20: =IF($I20>0,IF(K20>0,DATEDIF(I20,K20,"m"),"未完成"),"学员") -> 4 | K20: 43913 | L20: =IF($I20>0,IF(N20>0,DATEDIF(I20,N20,"m"),"未完成"),"学员") -> 24 | M20: =IF($I20>0,IF(N20>0,DATEDIF(K20,N20,"m"),"未完成"),"学员") -> 20 | N20: 44529 | O20: =IF($I20>0,IF(Q20>0,DATEDIF(I20,Q20,"m"),"未完成"),"学员") -> 57 | P20: =IF($I20>0,IF(Q20>0,DATEDIF(N20,Q20,"m"),"未完成"),"学员") -> 32 | Q20: 45520 | S20: =IF($I20>0,IF(T20>0,DATEDIF(I20,T20,"m"),"未完成"),"学员") -> 30 | T20: 44699 | U20: =IF($I20>0,IF(V20>0,DATEDIF(I20,V20,"m"),"未完成"),"学员") -> 44 | V20: 45126 | W20: =IF($I20>0,IF(X20>0,DATEDIF(I20,X20,"m"),"未完成"),"学员") -> 63 | X20: 45704 | Y20: =AA20+AC20+AE20+AH20+AJ20+AM20+AP20+AS20+AW20+AX20+AY20+AU20 -> 1025.429 | Z20: 是 | AA20: =IF(Z20="是",5,0) -> 5 | AB20: 是 | AC20: =IF(AB20="是",10,0) -> 10 | AD20: 是 | AE20: =IF(AD20="是",5,0) -> 5 | AF20: =COUNTA(K20,N20,Q20,R20)*10 -> 30 | AG20: =IF(N20>0,DATEDIF(N20,TODAY(),"m"),0) -> 49 | AH20: =AG20*3 -> 147 | AI20: =IF(Q20>0,DATEDIF(Q20,TODAY(),"m"),0) -> 17 | AJ20: =AI20*6 -> 102 | AK20: =IF(T20>0,10,0) -> 10 | AL20: =IF(T20>0,DATEDIF(T20,TODAY(),"m"),0) -> 43 | AM20: =AL20*6 -> 258 | AN20: =IF(V20>0,10,0) -> 10 | AO20: =IF(V20>0,DATEDIF(V20,TODAY(),"m"),0) -> 29 | AP20: =AO20*6 -> 174 | AQ20: =IF(X20>0,10,0) -> 10 | AR20: =IF(X20>0,DATEDIF(X20,TODAY(),"m"),0) -> 11 | AS20: =AR20*6 -> 66 | AT20: =VLOOKUP(B20,经历时间!A:B,2,FALSE) -> 2630.29 | AU20: =IF(Q20>0,AT20*0.1,0) -> 263.029 | AV20: =IF(I20>0,DATEDIF(I20,TODAY(),"m"),0) -> 74 | AW20: -4.6 | AY20: =IFERROR(VLOOKUP(B20,'兼职+帮忙'!B:AF,28,FALSE),0) -> 0
A21: 236217 | B21: 李泰成 | C21: =VLOOKUP(B21,'姓名+分部'!A:B,2,FALSE) -> 三分部 | D21: D | E21: =IF(Q21>0,RANK(Y21,Y$2:Y$133),"无排名") -> 6 | F21: =IF(AND(Y21>1000,Q21>0,T21>0,V21>0,AV21>48,AI21>3),"可流转","继续培训") -> 可流转 | G21: =IF(N21>0,"不考核",IF(K21>0,"B",IF(I21>0,"A2",IF(I21=0,"学员",NA())))) -> 不考核 | H21: =_xlfn.IFS(N21>0,"完成考核",K21>0,K21+390,I21>0,I21+120) -> 完成考核 | I21: 43053 | J21: =IF($I21>0,IF(K21>0,DATEDIF(I21,K21,"m"),"未完成"),"学员") -> 4 | K21: 43198 | L21: =IF($I21>0,IF(N21>0,DATEDIF(I21,N21,"m"),"未完成"),"学员") -> 35 | M21: =IF($I21>0,IF(N21>0,DATEDIF(K21,N21,"m"),"未完成"),"学员") -> 30 | N21: 44124 | O21: =IF($I21>0,IF(Q21>0,DATEDIF(I21,Q21,"m"),"未完成"),"学员") -> 65 | P21: =IF($I21>0,IF(Q21>0,DATEDIF(N21,Q21,"m"),"未完成"),"学员") -> 30 | Q21: 45036 | R21: 45750 | S21: =IF($I21>0,IF(T21>0,DATEDIF(I21,T21,"m"),"未完成"),"学员") -> 28 | T21: 43932 | U21: =IF($I21>0,IF(V21>0,DATEDIF(I21,V21,"m"),"未完成"),"学员") -> 23 | V21: 43767 | W21: =IF($I21>0,IF(X21>0,DATEDIF(I21,X21,"m"),"未完成"),"学员") -> 84 | X21: 45629 | Y21: =AA21+AC21+AE21+AH21+AJ21+AM21+AP21+AS21+AW21+AX21+AY21+AU21 -> 1714.3 | Z21: 是 | AA21: =IF(Z21="是",5,0) -> 5 | AB21: 是 | AC21: =IF(AB21="是",10,0) -> 10 | AD21: 是 | AE21: =IF(AD21="是",5,0) -> 5 | AF21: =COUNTA(K21,N21,Q21,R21)*10 -> 40 | AG21: =IF(N21>0,DATEDIF(N21,TODAY(),"m"),0) -> 62 | AH21: =AG21*3 -> 186 | AI21: =IF(Q21>0,DATEDIF(Q21,TODAY(),"m"),0) -> 32 | AJ21: =AI21*6 -> 192 | AK21: =IF(T21>0,10,0) -> 10 | AL21: =IF(T21>0,DATEDIF(T21,TODAY(),"m"),0) -> 69 | AM21: =AL21*6 -> 414 | AN21: =IF(V21>0,10,0) -> 10 | AO21: =IF(V21>0,DATEDIF(V21,TODAY(),"m"),0) -> 74 | AP21: =AO21*6 -> 444 | AQ21: =IF(X21>0,10,0) -> 10 | AR21: =IF(X21>0,DATEDIF(X21,TODAY(),"m"),0) -> 13 | AS21: =AR21*6 -> 78 | AT21: =VLOOKUP(B21,经历时间!A:B,2,FALSE) -> 3363 | AU21: =IF(Q21>0,AT21*0.1,0) -> 336.3 | AV21: =IF(I21>0,DATEDIF(I21,TODAY(),"m"),0) -> 98 | AW21: 32 | AY21: =IFERROR(VLOOKUP(B21,'兼职+帮忙'!B:AF,28,FALSE),0) -> 12
A22: 257603 | B22: 李少钦 | C22: =VLOOKUP(B22,'姓名+分部'!A:B,2,FALSE) -> 三分部 | D22: C | E22: =IF(Q22>0,RANK(Y22,Y$2:Y$133),"无排名") -> 23 | F22: =IF(AND(Y22>1000,Q22>0,T22>0,V22>0,AV22>48,AI22>3),"可流转","继续培训") -> 继续培训 | G22: =IF(N22>0,"不考核",IF(K22>0,"B",IF(I22>0,"A2",IF(I22=0,"学员",NA())))) -> 不考核 | H22: =_xlfn.IFS(N22>0,"完成考核",K22>0,K22+390,I22>0,I22+120) -> 完成考核 | I22: 43902 | J22: =IF($I22>0,IF(K22>0,DATEDIF(I22,K22,"m"),"未完成"),"学员") -> 10 | K22: 44230 | L22: =IF($I22>0,IF(N22>0,DATEDIF(I22,N22,"m"),"未完成"),"学员") -> 43 | M22: =IF($I22>0,IF(N22>0,DATEDIF(K22,N22,"m"),"未完成"),"学员") -> 32 | N22: 45215 | O22: =IF($I22>0,IF(Q22>0,DATEDIF(I22,Q22,"m"),"未完成"),"学员") -> 61 | P22: =IF($I22>0,IF(Q22>0,DATEDIF(N22,Q22,"m"),"未完成"),"学员") -> 18 | Q22: 45777 | S22: =IF($I22>0,IF(T22>0,DATEDIF(I22,T22,"m"),"未完成"),"学员") -> 37 | T22: 45050 | U22: =IF($I22>0,IF(V22>0,DATEDIF(I22,V22,"m"),"未完成"),"学员") -> 55 | V22: 45605 | W22: =IF($I22>0,IF(X22>0,DATEDIF(I22,X22,"m"),"未完成"),"学员") -> 未完成 | Y22: =AA22+AC22+AE22+AH22+AJ22+AM22+AP22+AS22+AW22+AX22+AY22+AU22 -> 691.242 | Z22: 是 | AA22: =IF(Z22="是",5,0) -> 5 | AB22: 是 | AC22: =IF(AB22="是",10,0) -> 10 | AD22: 是 | AE22: =IF(AD22="是",5,0) -> 5 | AF22: =COUNTA(K22,N22,Q22,R22)*10 -> 30 | AG22: =IF(N22>0,DATEDIF(N22,TODAY(),"m"),0) -> 27 | AH22: =AG22*3 -> 81 | AI22: =IF(Q22>0,DATEDIF(Q22,TODAY(),"m"),0) -> 8 | AJ22: =AI22*6 -> 48 | AK22: =IF(T22>0,10,0) -> 10 | AL22: =IF(T22>0,DATEDIF(T22,TODAY(),"m"),0) -> 32 | AM22: =AL22*6 -> 192 | AN22: =IF(V22>0,10,0) -> 10 | AO22: =IF(V22>0,DATEDIF(V22,TODAY(),"m"),0) -> 14 | AP22: =AO22*6 -> 84 | AQ22: =IF(X22>0,10,0) -> 0 | AR22: =IF(X22>0,DATEDIF(X22,TODAY(),"m"),0) -> 0 | AS22: =AR22*6 -> 0 | AT22: =VLOOKUP(B22,经历时间!A:B,2,FALSE) -> 2452.42 | AU22: =IF(Q22>0,AT22*0.1,0) -> 245.242 | AV22: =IF(I22>0,DATEDIF(I22,TODAY(),"m"),0) -> 70 | AW22: 18 | AX22: -5 | AY22: =IFERROR(VLOOKUP(B22,'兼职+帮忙'!B:AF,28,FALSE),0) -> 8
A23: 253772 | B23: 温健 | C23: =VLOOKUP(B23,'姓名+分部'!A:B,2,FALSE) -> 三分部 | D23: C | E23: =IF(Q23>0,RANK(Y23,Y$2:Y$133),"无排名") -> 25 | F23: =IF(AND(Y23>1000,Q23>0,T23>0,V23>0,AV23>48,AI23>3),"可流转","继续培训") -> 继续培训 | G23: =IF(N23>0,"不考核",IF(K23>0,"B",IF(I23>0,"A2",IF(I23=0,"学员",NA())))) -> 不考核 | H23: =_xlfn.IFS(N23>0,"完成考核",K23>0,K23+390,I23>0,I23+120) -> 完成考核 | I23: 43830 | J23: =IF($I23>0,IF(K23>0,DATEDIF(I23,K23,"m"),"未完成"),"学员") -> 11 | K23: 44190 | L23: =IF($I23>0,IF(N23>0,DATEDIF(I23,N23,"m"),"未完成"),"学员") -> 60 | M23: =IF($I23>0,IF(N23>0,DATEDIF(K23,N23,"m"),"未完成"),"学员") -> 48 | N23: 45679 | O23: =IF($I23>0,IF(Q23>0,DATEDIF(I23,Q23,"m"),"未完成"),"学员") -> 66 | P23: =IF($I23>0,IF(Q23>0,DATEDIF(N23,Q23,"m"),"未完成"),"学员") -> 5 | Q23: 45839 | S23: =IF($I23>0,IF(T23>0,DATEDIF(I23,T23,"m"),"未完成"),"学员") -> 38 | T23: 45009 | U23: =IF($I23>0,IF(V23>0,DATEDIF(I23,V23,"m"),"未完成"),"学员") -> 48 | V23: 45302 | W23: =IF($I23>0,IF(X23>0,DATEDIF(I23,X23,"m"),"未完成"),"学员") -> 未完成 | Y23: =AA23+AC23+AE23+AH23+AJ23+AM23+AP23+AS23+AW23+AX23+AY23+AU23 -> 659.802 | Z23: 是 | AA23: =IF(Z23="是",5,0) -> 5 | AB23: 是 | AC23: =IF(AB23="是",10,0) -> 10 | AD23: 是 | AE23: =IF(AD23="是",5,0) -> 5 | AF23: =COUNTA(K23,N23,Q23,R23)*10 -> 30 | AG23: =IF(N23>0,DATEDIF(N23,TODAY(),"m"),0) -> 11 | AH23: =AG23*3 -> 33 | AI23: =IF(Q23>0,DATEDIF(Q23,TODAY(),"m"),0) -> 6 | AJ23: =AI23*6 -> 36 | AK23: =IF(T23>0,10,0) -> 10 | AL23: =IF(T23>0,DATEDIF(T23,TODAY(),"m"),0) -> 33 | AM23: =AL23*6 -> 198 | AN23: =IF(V23>0,10,0) -> 10 | AO23: =IF(V23>0,DATEDIF(V23,TODAY(),"m"),0) -> 24 | AP23: =AO23*6 -> 144 | AQ23: =IF(X23>0,10,0) -> 0 | AR23: =IF(X23>0,DATEDIF(X23,TODAY(),"m"),0) -> 0 | AS23: =AR23*6 -> 0 | AT23: =VLOOKUP(B23,经历时间!A:B,2,FALSE) -> 2287.02 | AU23: =IF(Q23>0,AT23*0.1,0) -> 228.702 | AV23: =IF(I23>0,DATEDIF(I23,TODAY(),"m"),0) -> 72 | AW23: 0.1 | AY23: =IFERROR(VLOOKUP(B23,'兼职+帮忙'!B:AF,28,FALSE),0) -> 0
A24: 230397 | B24: 谢旭纬 | C24: =VLOOKUP(B24,'姓名+分部'!A:B,2,FALSE) -> 二分部 | D24: C | E24: =IF(Q24>0,RANK(Y24,Y$2:Y$133),"无排名") -> 9 | F24: =IF(AND(Y24>1000,Q24>0,T24>0,V24>0,AV24>48,AI24>3),"可流转","继续培训") -> 可流转 | G24: =IF(N24>0,"不考核",IF(K24>0,"B",IF(I24>0,"A2",IF(I24=0,"学员",NA())))) -> 不考核 | H24: =_xlfn.IFS(N24>0,"完成考核",K24>0,K24+390,I24>0,I24+120) -> 完成考核 | I24: 43734 | J24: =IF($I24>0,IF(K24>0,DATEDIF(I24,K24,"m"),"未完成"),"学员") -> 0 | K24: 43760 | L24: =IF($I24>0,IF(N24>0,DATEDIF(I24,N24,"m"),"未完成"),"学员") -> 32 | M24: =IF($I24>0,IF(N24>0,DATEDIF(K24,N24,"m"),"未完成"),"学员") -> 31 | N24: 44716 | O24: =IF($I24>0,IF(Q24>0,DATEDIF(I24,Q24,"m"),"未完成"),"学员") -> 47 | P24: =IF($I24>0,IF(Q24>0,DATEDIF(N24,Q24,"m"),"未完成"),"学员") -> 14 | Q24: 45170 | S24: =IF($I24>0,IF(T24>0,DATEDIF(I24,T24,"m"),"未完成"),"学员") -> 30 | T24: 44667 | U24: =IF($I24>0,IF(V24>0,DATEDIF(I24,V24,"m"),"未完成"),"学员") -> 16 | V24: 44247 | W24: =IF($I24>0,IF(X24>0,DATEDIF(I24,X24,"m"),"未完成"),"学员") -> 未完成 | Y24: =AA24+AC24+AE24+AH24+AJ24+AM24+AP24+AS24+AW24+AX24+AY24+AU24 -> 1223.804 | Z24: 是 | AA24: =IF(Z24="是",5,0) -> 5 | AB24: 是 | AC24: =IF(AB24="是",10,0) -> 10 | AD24: 是 | AE24: =IF(AD24="是",5,0) -> 5 | AF24: =COUNTA(K24,N24,Q24,R24)*10 -> 30 | AG24: =IF(N24>0,DATEDIF(N24,TODAY(),"m"),0) -> 43 | AH24: =AG24*3 -> 129 | AI24: =IF(Q24>0,DATEDIF(Q24,TODAY(),"m"),0) -> 28 | AJ24: =AI24*6 -> 168 | AK24: =IF(T24>0,10,0) -> 10 | AL24: =IF(T24>0,DATEDIF(T24,TODAY(),"m"),0) -> 45 | AM24: =AL24*6 -> 270 | AN24: =IF(V24>0,10,0) -> 10 | AO24: =IF(V24>0,DATEDIF(V24,TODAY(),"m"),0) -> 58 | AP24: =AO24*6 -> 348 | AQ24: =IF(X24>0,10,0) -> 0 | AR24: =IF(X24>0,DATEDIF(X24,TODAY(),"m"),0) -> 0 | AS24: =AR24*6 -> 0 | AT24: =VLOOKUP(B24,经历时间!A:B,2,FALSE) -> 2868.04 | AU24: =IF(Q24>0,AT24*0.1,0) -> 286.804 | AV24: =IF(I24>0,DATEDIF(I24,TODAY(),"m"),0) -> 75 | AW24: 1 | AY24: =IFERROR(VLOOKUP(B24,'兼职+帮忙'!B:AF,28,FALSE),0) -> 1
A25: 261764 | B25: 袁珂 | C25: =VLOOKUP(B25,'姓名+分部'!A:B,2,FALSE) -> 三分部 | D25: C | E25: =IF(Q25>0,RANK(Y25,Y$2:Y$133),"无排名") -> 22 | F25: =IF(AND(Y25>1000,Q25>0,T25>0,V25>0,AV25>48,AI25>3),"可流转","继续培训") -> 继续培训 | G25: =IF(N25>0,"不考核",IF(K25>0,"B",IF(I25>0,"A2",IF(I25=0,"学员",NA())))) -> 不考核 | H25: =_xlfn.IFS(N25>0,"完成考核",K25>0,K25+390,I25>0,I25+120) -> 完成考核 | I25: 44407 | J25: =IF($I25>0,IF(K25>0,DATEDIF(I25,K25,"m"),"未完成"),"学员") -> 14 | K25: 44847 | L25: =IF($I25>0,IF(N25>0,DATEDIF(I25,N25,"m"),"未完成"),"学员") -> 29 | M25: =IF($I25>0,IF(N25>0,DATEDIF(K25,N25,"m"),"未完成"),"学员") -> 15 | N25: 45306 | O25: =IF($I25>0,IF(Q25>0,DATEDIF(I25,Q25,"m"),"未完成"),"学员") -> 38 | P25: =IF($I25>0,IF(Q25>0,DATEDIF(N25,Q25,"m"),"未完成"),"学员") -> 8 | Q25: 45571 | S25: =IF($I25>0,IF(T25>0,DATEDIF(I25,T25,"m"),"未完成"),"学员") -> 19 | T25: 45009 | U25: =IF($I25>0,IF(V25>0,DATEDIF(I25,V25,"m"),"未完成"),"学员") -> 32 | V25: 45397 | W25: =IF($I25>0,IF(X25>0,DATEDIF(I25,X25,"m"),"未完成"),"学员") -> 未完成 | Y25: =AA25+AC25+AE25+AH25+AJ25+AM25+AP25+AS25+AW25+AX25+AY25+AU25 -> 691.256 | Z25: 是 | AA25: =IF(Z25="是",5,0) -> 5 | AB25: 是 | AC25: =IF(AB25="是",10,0) -> 10 | AD25: 是 | AE25: =IF(AD25="是",5,0) -> 5 | AF25: =COUNTA(K25,N25,Q25,R25)*10 -> 30 | AG25: =IF(N25>0,DATEDIF(N25,TODAY(),"m"),0) -> 24 | AH25: =AG25*3 -> 72 | AI25: =IF(Q25>0,DATEDIF(Q25,TODAY(),"m"),0) -> 15 | AJ25: =AI25*6 -> 90 | AK25: =IF(T25>0,10,0) -> 10 | AL25: =IF(T25>0,DATEDIF(T25,TODAY(),"m"),0) -> 33 | AM25: =AL25*6 -> 198 | AN25: =IF(V25>0,10,0) -> 10 | AO25: =IF(V25>0,DATEDIF(V25,TODAY(),"m"),0) -> 21 | AP25: =AO25*6 -> 126 | AQ25: =IF(X25>0,10,0) -> 0 | AR25: =IF(X25>0,DATEDIF(X25,TODAY(),"m"),0) -> 0 | AS25: =AR25*6 -> 0 | AT25: =VLOOKUP(B25,经历时间!A:B,2,FALSE) -> 1850.56 | AU25: =IF(Q25>0,AT25*0.1,0) -> 185.056 | AV25: =IF(I25>0,DATEDIF(I25,TODAY(),"m"),0) -> 53 | AW25: 0.2 | AY25: =IFERROR(VLOOKUP(B25,'兼职+帮忙'!B:AF,28,FALSE),0) -> 0
A26: 265806 | B26: 陈伯楠 | C26: =VLOOKUP(B26,'姓名+分部'!A:B,2,FALSE) -> 三分部 | D26: C | E26: =IF(Q26>0,RANK(Y26,Y$2:Y$133),"无排名") -> 24 | F26: =IF(AND(Y26>1000,Q26>0,T26>0,V26>0,AV26>48,AI26>3),"可流转","继续培训") -> 继续培训 | G26: =IF(N26>0,"不考核",IF(K26>0,"B",IF(I26>0,"A2",IF(I26=0,"学员",NA())))) -> 不考核 | H26: =_xlfn.IFS(N26>0,"完成考核",K26>0,K26+390,I26>0,I26+120) -> 完成考核 | I26: 44420 | J26: =IF($I26>0,IF(K26>0,DATEDIF(I26,K26,"m"),"未完成"),"学员") -> 9 | K26: 44719 | L26: =IF($I26>0,IF(N26>0,DATEDIF(I26,N26,"m"),"未完成"),"学员") -> 33 | M26: =IF($I26>0,IF(N26>0,DATEDIF(K26,N26,"m"),"未完成"),"学员") -> 23 | N26: 45432 | O26: =IF($I26>0,IF(Q26>0,DATEDIF(I26,Q26,"m"),"未完成"),"学员") -> 41 | P26: =IF($I26>0,IF(Q26>0,DATEDIF(N26,Q26,"m"),"未完成"),"学员") -> 8 | Q26: 45693 | S26: =IF($I26>0,IF(T26>0,DATEDIF(I26,T26,"m"),"未完成"),"学员") -> 24 | T26: 45152 | U26: =IF($I26>0,IF(V26>0,DATEDIF(I26,V26,"m"),"未完成"),"学员") -> 32 | V26: 45397 | W26: =IF($I26>0,IF(X26>0,DATEDIF(I26,X26,"m"),"未完成"),"学员") -> 未完成 | Y26: =AA26+AC26+AE26+AH26+AJ26+AM26+AP26+AS26+AW26+AX26+AY26+AU26 -> 660.536 | Z26: 是 | AA26: =IF(Z26="是",5,0) -> 5 | AB26: 是 | AC26: =IF(AB26="是",10,0) -> 10 | AD26: 是 | AE26: =IF(AD26="是",5,0) -> 5 | AF26: =COUNTA(K26,N26,Q26,R26)*10 -> 30 | AG26: =IF(N26>0,DATEDIF(N26,TODAY(),"m"),0) -> 19 | AH26: =AG26*3 -> 57 | AI26: =IF(Q26>0,DATEDIF(Q26,TODAY(),"m"),0) -> 11 | AJ26: =AI26*6 -> 66 | AK26: =IF(T26>0,10,0) -> 10 | AL26: =IF(T26>0,DATEDIF(T26,TODAY(),"m"),0) -> 29 | AM26: =AL26*6 -> 174 | AN26: =IF(V26>0,10,0) -> 10 | AO26: =IF(V26>0,DATEDIF(V26,TODAY(),"m"),0) -> 21 | AP26: =AO26*6 -> 126 | AQ26: =IF(X26>0,10,0) -> 0 | AR26: =IF(X26>0,DATEDIF(X26,TODAY(),"m"),0) -> 0 | AS26: =AR26*6 -> 0 | AT26: =VLOOKUP(B26,经历时间!A:B,2,FALSE) -> 2175.36 | AU26: =IF(Q26>0,AT26*0.1,0) -> 217.536 | AV26: =IF(I26>0,DATEDIF(I26,TODAY(),"m"),0) -> 53 | AW26: 0 | AY26: =IFERROR(VLOOKUP(B26,'兼职+帮忙'!B:AF,28,FALSE),0) -> 0
A27: 253776 | B27: 张星远 | C27: =VLOOKUP(B27,'姓名+分部'!A:B,2,FALSE) -> 二分部 | D27: B | E27: =IF(Q27>0,RANK(Y27,Y$2:Y$133),"无排名") -> 无排名 | F27: =IF(AND(Y27>1000,Q27>0,T27>0,V27>0,AV27>48,AI27>3),"可流转","继续培训") -> 继续培训 | G27: =IF(N27>0,"不考核",IF(K27>0,"B",IF(I27>0,"A2",IF(I27=0,"学员",NA())))) -> 不考核 | H27: =_xlfn.IFS(N27>0,"完成考核",K27>0,K27+390,I27>0,I27+120) -> 完成考核 | I27: 43865 | J27: =IF($I27>0,IF(K27>0,DATEDIF(I27,K27,"m"),"未完成"),"学员") -> 10 | K27: 44187 | L27: =IF($I27>0,IF(N27>0,DATEDIF(I27,N27,"m"),"未完成"),"学员") -> 45 | M27: =IF($I27>0,IF(N27>0,DATEDIF(K27,N27,"m"),"未完成"),"学员") -> 34 | N27: 45243 | O27: =IF($I27>0,IF(Q27>0,DATEDIF(I27,Q27,"m"),"未完成"),"学员") -> 未完成 | P27: =IF($I27>0,IF(Q27>0,DATEDIF(N27,Q27,"m"),"未完成"),"学员") -> 未完成 | S27: =IF($I27>0,IF(T27>0,DATEDIF(I27,T27,"m"),"未完成"),"学员") -> 37 | T27: 45009 | U27: =IF($I27>0,IF(V27>0,DATEDIF(I27,V27,"m"),"未完成"),"学员") -> 42 | V27: 45155 | W27: =IF($I27>0,IF(X27>0,DATEDIF(I27,X27,"m"),"未完成"),"学员") -> 未完成 | Y27: =AA27+AC27+AE27+AH27+AJ27+AM27+AP27+AS27+AW27+AX27+AY27+AU27 -> 470.4 | Z27: 是 | AA27: =IF(Z27="是",5,0) -> 5 | AB27: 是 | AC27: =IF(AB27="是",10,0) -> 10 | AD27: 是 | AE27: =IF(AD27="是",5,0) -> 5 | AF27: =COUNTA(K27,N27,Q27,R27)*10 -> 20 | AG27: =IF(N27>0,DATEDIF(N27,TODAY(),"m"),0) -> 26 | AH27: =AG27*3 -> 78 | AI27: =IF(Q27>0,DATEDIF(Q27,TODAY(),"m"),0) -> 0 | AJ27: =AI27*6 -> 0 | AK27: =IF(T27>0,10,0) -> 10 | AL27: =IF(T27>0,DATEDIF(T27,TODAY(),"m"),0) -> 33 | AM27: =AL27*6 -> 198 | AN27: =IF(V27>0,10,0) -> 10 | AO27: =IF(V27>0,DATEDIF(V27,TODAY(),"m"),0) -> 28 | AP27: =AO27*6 -> 168 | AQ27: =IF(X27>0,10,0) -> 0 | AR27: =IF(X27>0,DATEDIF(X27,TODAY(),"m"),0) -> 0 | AS27: =AR27*6 -> 0 | AT27: =VLOOKUP(B27,经历时间!A:B,2,FALSE) -> 2321.23 | AU27: =IF(Q27>0,AT27*0.1,0) -> 0 | AV27: =IF(I27>0,DATEDIF(I27,TODAY(),"m"),0) -> 71 | AW27: 1.4 | AY27: =IFERROR(VLOOKUP(B27,'兼职+帮忙'!B:AF,28,FALSE),0) -> 5
A28: 257697 | B28: 胡金鑫 | C28: =VLOOKUP(B28,'姓名+分部'!A:B,2,FALSE) -> 三分部 | D28: C | E28: =IF(Q28>0,RANK(Y28,Y$2:Y$133),"无排名") -> 26 | F28: =IF(AND(Y28>1000,Q28>0,T28>0,V28>0,AV28>48,AI28>3),"可流转","继续培训") -> 继续培训 | G28: =IF(N28>0,"不考核",IF(K28>0,"B",IF(I28>0,"A2",IF(I28=0,"学员",NA())))) -> 不考核 | H28: =_xlfn.IFS(N28>0,"完成考核",K28>0,K28+390,I28>0,I28+120) -> 完成考核 | I28: 44116 | J28: =IF($I28>0,IF(K28>0,DATEDIF(I28,K28,"m"),"未完成"),"学员") -> 6 | K28: 44309 | L28: =IF($I28>0,IF(N28>0,DATEDIF(I28,N28,"m"),"未完成"),"学员") -> 29 | M28: =IF($I28>0,IF(N28>0,DATEDIF(K28,N28,"m"),"未完成"),"学员") -> 23 | N28: 45012 | O28: =IF($I28>0,IF(Q28>0,DATEDIF(I28,Q28,"m"),"未完成"),"学员") -> 60 | P28: =IF($I28>0,IF(Q28>0,DATEDIF(N28,Q28,"m"),"未完成"),"学员") -> 31 | Q28: 45959 | S28: =IF($I28>0,IF(T28>0,DATEDIF(I28,T28,"m"),"未完成"),"学员") -> 43 | T28: 45454 | U28: =IF($I28>0,IF(V28>0,DATEDIF(I28,V28,"m"),"未完成"),"学员") -> 35 | V28: 45181 | W28: =IF($I28>0,IF(X28>0,DATEDIF(I28,X28,"m"),"未完成"),"学员") -> 未完成 | Y28: =AA28+AC28+AE28+AH28+AJ28+AM28+AP28+AS28+AW28+AX28+AY28+AU28 -> 651.346 | Z28: 是 | AA28: =IF(Z28="是",5,0) -> 5 | AB28: 是 | AC28: =IF(AB28="是",10,0) -> 10 | AD28: 是 | AE28: =IF(AD28="是",5,0) -> 5 | AF28: =COUNTA(K28,N28,Q28,R28)*10 -> 30 | AG28: =IF(N28>0,DATEDIF(N28,TODAY(),"m"),0) -> 33 | AH28: =AG28*3 -> 99 | AI28: =IF(Q28>0,DATEDIF(Q28,TODAY(),"m"),0) -> 2 | AJ28: =AI28*6 -> 12 | AK28: =IF(T28>0,10,0) -> 10 | AL28: =IF(T28>0,DATEDIF(T28,TODAY(),"m"),0) -> 19 | AM28: =AL28*6 -> 114 | AN28: =IF(V28>0,10,0) -> 10 | AO28: =IF(V28>0,DATEDIF(V28,TODAY(),"m"),0) -> 28 | AP28: =AO28*6 -> 168 | AQ28: =IF(X28>0,10,0) -> 0 | AR28: =IF(X28>0,DATEDIF(X28,TODAY(),"m"),0) -> 0 | AS28: =AR28*6 -> 0 | AT28: =VLOOKUP(B28,经历时间!A:B,2,FALSE) -> 2123.46 | AU28: =IF(Q28>0,AT28*0.1,0) -> 212.346 | AV28: =IF(I28>0,DATEDIF(I28,TODAY(),"m"),0) -> 63 | AW28: 26 | AY28: =IFERROR(VLOOKUP(B28,'兼职+帮忙'!B:AF,28,FALSE),0) -> 0
A29: 266464 | B29: 王程乾 | C29: =VLOOKUP(B29,'姓名+分部'!A:B,2,FALSE) -> 二分部 | D29: B | E29: =IF(Q29>0,RANK(Y29,Y$2:Y$133),"无排名") -> 无排名 | F29: =IF(AND(Y29>1000,Q29>0,T29>0,V29>0,AV29>48,AI29>3),"可流转","继续培训") -> 继续培训 | G29: =IF(N29>0,"不考核",IF(K29>0,"B",IF(I29>0,"A2",IF(I29=0,"学员",NA())))) -> 不考核 | H29: =_xlfn.IFS(N29>0,"完成考核",K29>0,K29+390,I29>0,I29+120) -> 完成考核 | I29: 44384 | J29: =IF($I29>0,IF(K29>0,DATEDIF(I29,K29,"m"),"未完成"),"学员") -> 12 | K29: 44769 | L29: =IF($I29>0,IF(N29>0,DATEDIF(I29,N29,"m"),"未完成"),"学员") -> 26 | M29: =IF($I29>0,IF(N29>0,DATEDIF(K29,N29,"m"),"未完成"),"学员") -> 13 | N29: 45185 | O29: =IF($I29>0,IF(Q29>0,DATEDIF(I29,Q29,"m"),"未完成"),"学员") -> 未完成 | P29: =IF($I29>0,IF(Q29>0,DATEDIF(N29,Q29,"m"),"未完成"),"学员") -> 未完成 | S29: =IF($I29>0,IF(T29>0,DATEDIF(I29,T29,"m"),"未完成"),"学员") -> 34 | T29: 45445 | U29: =IF($I29>0,IF(V29>0,DATEDIF(I29,V29,"m"),"未完成"),"学员") -> 26 | V29: 45181 | W29: =IF($I29>0,IF(X29>0,DATEDIF(I29,X29,"m"),"未完成"),"学员") -> 未完成 | Y29: =AA29+AC29+AE29+AH29+AJ29+AM29+AP29+AS29+AW29+AX29+AY29+AU29 -> 413 | Z29: 是 | AA29: =IF(Z29="是",5,0) -> 5 | AB29: 是 | AC29: =IF(AB29="是",10,0) -> 10 | AD29: 是 | AE29: =IF(AD29="是",5,0) -> 5 | AF29: =COUNTA(K29,N29,Q29,R29)*10 -> 20 | AG29: =IF(N29>0,DATEDIF(N29,TODAY(),"m"),0) -> 28 | AH29: =AG29*3 -> 84 | AI29: =IF(Q29>0,DATEDIF(Q29,TODAY(),"m"),0) -> 0 | AJ29: =AI29*6 -> 0 | AK29: =IF(T29>0,10,0) -> 10 | AL29: =IF(T29>0,DATEDIF(T29,TODAY(),"m"),0) -> 19 | AM29: =AL29*6 -> 114 | AN29: =IF(V29>0,10,0) -> 10 | AO29: =IF(V29>0,DATEDIF(V29,TODAY(),"m"),0) -> 28 | AP29: =AO29*6 -> 168 | AQ29: =IF(X29>0,10,0) -> 0 | AR29: =IF(X29>0,DATEDIF(X29,TODAY(),"m"),0) -> 0 | AS29: =AR29*6 -> 0 | AT29: =VLOOKUP(B29,经历时间!A:B,2,FALSE) -> 1872.08 | AU29: =IF(Q29>0,AT29*0.1,0) -> 0 | AV29: =IF(I29>0,DATEDIF(I29,TODAY(),"m"),0) -> 54 | AW29: 27 | AY29: =IFERROR(VLOOKUP(B29,'兼职+帮忙'!B:AF,28,FALSE),0) -> 0
A30: 246412 | B30: 邓汉昕 | C30: =VLOOKUP(B30,'姓名+分部'!A:B,2,FALSE) -> 三分部 | D30: B | E30: =IF(Q30>0,RANK(Y30,Y$2:Y$133),"无排名") -> 无排名 | F30: =IF(AND(Y30>1000,Q30>0,T30>0,V30>0,AV30>48,AI30>3),"可流转","继续培训") -> 继续培训 | G30: =IF(N30>0,"不考核",IF(K30>0,"B",IF(I30>0,"A2",IF(I30=0,"学员",NA())))) -> 不考核 | H30: =_xlfn.IFS(N30>0,"完成考核",K30>0,K30+390,I30>0,I30+120) -> 完成考核 | I30: 43839 | J30: =IF($I30>0,IF(K30>0,DATEDIF(I30,K30,"m"),"未完成"),"学员") -> 13 | K30: 44253 | L30: =IF($I30>0,IF(N30>0,DATEDIF(I30,N30,"m"),"未完成"),"学员") -> 43 | M30: =IF($I30>0,IF(N30>0,DATEDIF(K30,N30,"m"),"未完成"),"学员") -> 29 | N30: 45157 | O30: =IF($I30>0,IF(Q30>0,DATEDIF(I30,Q30,"m"),"未完成"),"学员") -> 未完成 | P30: =IF($I30>0,IF(Q30>0,DATEDIF(N30,Q30,"m"),"未完成"),"学员") -> 未完成 | S30: =IF($I30>0,IF(T30>0,DATEDIF(I30,T30,"m"),"未完成"),"学员") -> 39 | T30: 45042 | U30: =IF($I30>0,IF(V30>0,DATEDIF(I30,V30,"m"),"未完成"),"学员") -> 未完成 | W30: =IF($I30>0,IF(X30>0,DATEDIF(I30,X30,"m"),"未完成"),"学员") -> 61 | X30: 45723 | Y30: =AA30+AC30+AE30+AH30+AJ30+AM30+AP30+AS30+AW30+AX30+AY30+AU30 -> 356 | Z30: 是 | AA30: =IF(Z30="是",5,0) -> 5 | AB30: 是 | AC30: =IF(AB30="是",10,0) -> 10 | AD30: 是 | AE30: =IF(AD30="是",5,0) -> 5 | AF30: =COUNTA(K30,N30,Q30,R30)*10 -> 20 | AG30: =IF(N30>0,DATEDIF(N30,TODAY(),"m"),0) -> 28 | AH30: =AG30*3 -> 84 | AI30: =IF(Q30>0,DATEDIF(Q30,TODAY(),"m"),0) -> 0 | AJ30: =AI30*6 -> 0 | AK30: =IF(T30>0,10,0) -> 10 | AL30: =IF(T30>0,DATEDIF(T30,TODAY(),"m"),0) -> 32 | AM30: =AL30*6 -> 192 | AN30: =IF(V30>0,10,0) -> 0 | AO30: =IF(V30>0,DATEDIF(V30,TODAY(),"m"),0) -> 0 | AP30: =AO30*6 -> 0 | AQ30: =IF(X30>0,10,0) -> 10 | AR30: =IF(X30>0,DATEDIF(X30,TODAY(),"m"),0) -> 10 | AS30: =AR30*6 -> 60 | AT30: =VLOOKUP(B30,经历时间!A:B,2,FALSE) -> 2099.32 | AU30: =IF(Q30>0,AT30*0.1,0) -> 0 | AW30: 0 | AY30: =IFERROR(VLOOKUP(B30,'兼职+帮忙'!B:AF,28,FALSE),0) -> 0
A31: 264179 | B31: 李天诚 | C31: =VLOOKUP(B31,'姓名+分部'!A:B,2,FALSE) -> 一分部 | D31: B | E31: =IF(Q31>0,RANK(Y31,Y$2:Y$133),"无排名") -> 无排名 | F31: =IF(AND(Y31>1000,Q31>0,T31>0,V31>0,AV31>48,AI31>3),"可流转","继续培训") -> 继续培训 | G31: =IF(N31>0,"不考核",IF(K31>0,"B",IF(I31>0,"A2",IF(I31=0,"学员",NA())))) -> 不考核 | H31: =_xlfn.IFS(N31>0,"完成考核",K31>0,K31+390,I31>0,I31+120) -> 完成考核 | I31: 44915 | J31: =IF($I31>0,IF(K31>0,DATEDIF(I31,K31,"m"),"未完成"),"学员") -> 10 | K31: 45223 | L31: =IF($I31>0,IF(N31>0,DATEDIF(I31,N31,"m"),"未完成"),"学员") -> 18 | M31: =IF($I31>0,IF(N31>0,DATEDIF(K31,N31,"m"),"未完成"),"学员") -> 8 | N31: 45469 | O31: =IF($I31>0,IF(Q31>0,DATEDIF(I31,Q31,"m"),"未完成"),"学员") -> 未完成 | P31: =IF($I31>0,IF(Q31>0,DATEDIF(N31,Q31,"m"),"未完成"),"学员") -> 未完成 | S31: =IF($I31>0,IF(T31>0,DATEDIF(I31,T31,"m"),"未完成"),"学员") -> 7 | T31: 45132 | U31: =IF($I31>0,IF(V31>0,DATEDIF(I31,V31,"m"),"未完成"),"学员") -> 22 | V31: 45602 | W31: =IF($I31>0,IF(X31>0,DATEDIF(I31,X31,"m"),"未完成"),"学员") -> 未完成 | Y31: =AA31+AC31+AE31+AH31+AJ31+AM31+AP31+AS31+AW31+AX31+AY31+AU31 -> 327 | Z31: 是 | AA31: =IF(Z31="是",5,0) -> 5 | AB31: 是 | AC31: =IF(AB31="是",10,0) -> 10 | AD31: 是 | AE31: =IF(AD31="是",5,0) -> 5 | AF31: =COUNTA(K31,N31,Q31,R31)*10 -> 20 | AG31: =IF(N31>0,DATEDIF(N31,TODAY(),"m"),0) -> 18 | AH31: =AG31*3 -> 54 | AI31: =IF(Q31>0,DATEDIF(Q31,TODAY(),"m"),0) -> 0 | AJ31: =AI31*6 -> 0 | AK31: =IF(T31>0,10,0) -> 10 | AL31: =IF(T31>0,DATEDIF(T31,TODAY(),"m"),0) -> 29 | AM31: =AL31*6 -> 174 | AN31: =IF(V31>0,10,0) -> 10 | AO31: =IF(V31>0,DATEDIF(V31,TODAY(),"m"),0) -> 14 | AP31: =AO31*6 -> 84 | AQ31: =IF(X31>0,10,0) -> 0 | AR31: =IF(X31>0,DATEDIF(X31,TODAY(),"m"),0) -> 0 | AS31: =AR31*6 -> 0 | AT31: =VLOOKUP(B31,经历时间!A:B,2,FALSE) -> 2040.45 | AU31: =IF(Q31>0,AT31*0.1,0) -> 0 | AV31: =IF(I31>0,DATEDIF(I31,TODAY(),"m"),0) -> 36 | AW31: 0 | AX31: -5 | AY31: =IFERROR(VLOOKUP(B31,'兼职+帮忙'!B:AF,28,FALSE),0) -> 0
A32: 265822 | B32: 谢源 | C32: =VLOOKUP(B32,'姓名+分部'!A:B,2,FALSE) -> 二分部 | D32: C | E32: =IF(Q32>0,RANK(Y32,Y$2:Y$133),"无排名") -> 27 | F32: =IF(AND(Y32>1000,Q32>0,T32>0,V32>0,AV32>48,AI32>3),"可流转","继续培训") -> 继续培训 | G32: =IF(N32>0,"不考核",IF(K32>0,"B",IF(I32>0,"A2",IF(I32=0,"学员",NA())))) -> 不考核 | H32: =_xlfn.IFS(N32>0,"完成考核",K32>0,K32+390,I32>0,I32+120) -> 完成考核 | I32: 44385 | J32: =IF($I32>0,IF(K32>0,DATEDIF(I32,K32,"m"),"未完成"),"学员") -> 5 | K32: 44564 | L32: =IF($I32>0,IF(N32>0,DATEDIF(I32,N32,"m"),"未完成"),"学员") -> 39 | M32: =IF($I32>0,IF(N32>0,DATEDIF(K32,N32,"m"),"未完成"),"学员") -> 33 | N32: 45587 | O32: =IF($I32>0,IF(Q32>0,DATEDIF(I32,Q32,"m"),"未完成"),"学员") -> 51 | P32: =IF($I32>0,IF(Q32>0,DATEDIF(N32,Q32,"m"),"未完成"),"学员") -> 12 | Q32: 45959 | S32: =IF($I32>0,IF(T32>0,DATEDIF(I32,T32,"m"),"未完成"),"学员") -> 30 | T32: 45320 | U32: =IF($I32>0,IF(V32>0,DATEDIF(I32,V32,"m"),"未完成"),"学员") -> 35 | V32: 45475 | W32: =IF($I32>0,IF(X32>0,DATEDIF(I32,X32,"m"),"未完成"),"学员") -> 未完成 | Y32: =AA32+AC32+AE32+AH32+AJ32+AM32+AP32+AS32+AW32+AX32+AY32+AU32 -> 630.631 | Z32: 是 | AA32: =IF(Z32="是",5,0) -> 5 | AB32: 是 | AC32: =IF(AB32="是",10,0) -> 10 | AD32: 是 | AE32: =IF(AD32="是",5,0) -> 5 | AF32: =COUNTA(K32,N32,Q32,R32)*10 -> 30 | AG32: =IF(N32>0,DATEDIF(N32,TODAY(),"m"),0) -> 14 | AH32: =AG32*3 -> 42 | AI32: =IF(Q32>0,DATEDIF(Q32,TODAY(),"m"),0) -> 2 | AJ32: =AI32*6 -> 12 | AK32: =IF(T32>0,10,0) -> 10 | AL32: =IF(T32>0,DATEDIF(T32,TODAY(),"m"),0) -> 23 | AM32: =AL32*6 -> 138 | AN32: =IF(V32>0,10,0) -> 10 | AO32: =IF(V32>0,DATEDIF(V32,TODAY(),"m"),0) -> 18 | AP32: =AO32*6 -> 108 | AQ32: =IF(X32>0,10,0) -> 0 | AR32: =IF(X32>0,DATEDIF(X32,TODAY(),"m"),0) -> 0 | AS32: =AR32*6 -> 0 | AT32: =VLOOKUP(B32,经历时间!A:B,2,FALSE) -> 1436.31 | AU32: =IF(Q32>0,AT32*0.1,0) -> 143.631 | AV32: =IF(I32>0,DATEDIF(I32,TODAY(),"m"),0) -> 54 | AW32: 6 | AY32: =IFERROR(VLOOKUP(B32,'兼职+帮忙'!B:AF,28,FALSE),0) -> 161
